Workbook

Sheet Inputs
A1: Citizens Standard — Interactive Model Builder
A2: Adjust the yellow cells; everything else recalculates. Mode A = maximum wealth (deflation). Mode B = stable prices. Mode C = monthly dividend (inflation). See Mode Presets sheet for reference values.
A4: Parameter | B4: Value | C4: Unit | D4: Notes
A5: Issuance channels (K-values)
A6: K1 — Citizenship endowment | B6: 0.025 | C6: % of GDP/capita per new citizen | D6: Mode A: 2.5%. Constitutional ceiling 5% (normal), 7.5% emergency.
A7: K2 — Growth dividend | B7: 0.125 | C7: % of real growth, distributed equally | D7: Mode A: 12.5%. Mode B: ~84% (or whatever closes to real_growth × M2). Constitutional ceiling 25%.
A8: K3 — Citizen dividend | B8: 0 | C8: % of M2 issued annually as monthly dividend | D8: Mode A & B: 0%. Mode C: ~4% (calibrated to hit 2% inflation target).
A10: Macro environment
A11: Real GDP growth rate | B11: 0.02 | C11: annual | D11: Long-run US average ~2%. Drops in recessions.
A12: Population growth rate | B12: 0.005 | C12: annual | D12: US recent: 0.5%. Sets new-citizen K1 deposits.
A13: CPI inflation rate | B13: 0 | C13: annual, target | D13: Mode A: -1.6%. Mode B: 0%. Mode C: 2.0%.
A14: Equity index real return | B14: 0.065 | C14: annual | D14: Stable Floor compounds at this rate (after-inflation if CPI=0; nominal otherwise — see notes).
A16: Launch conditions (year 0)
A17: M2 money supply | B17: 22700000000000 | C17: dollars | D17: US M2 in launch year. Determines circulating pool size.
A18: Nominal GDP | B18: 30700000000000 | C18: dollars | D18: US GDP in launch year.
A19: Population | B19: 342000000 | C19: citizens | D19: Verified citizens at launch.
A20: Projection horizon | B20: 65 | C20: years | D20: Cohort tracked from age 0 to this age.
A21: Withdrawal rate at horizon | B21: 0.04 | C21: % of Stable Floor | D21: Conventional 4% safe withdrawal rate.

Sheet Projection
A1: Year-by-year simulation
A2: All values computed from Inputs. Black text = formulas. Do not edit.
A4: Year | B4: M2 ($) | C4: GDP ($) | D4: Population | E4: CPI index | F4: Births | G4: K1 total ($) | H4: K2 total ($) | I4: K3 total ($) | J4: K2 / citizen | K4: K3 monthly / citizen | L4: Cohort floor (nominal $) | M4: Cohort floor (real $) | N4: Cohort K3 cumulative (real $)
A5: 0 | B5: =Inputs!B17 -> 22700000000000 | C5: =Inputs!B18 -> 30700000000000 | D5: =Inputs!B19 -> 342000000 | E5: 1 | F5: =MAX(0,D5*Inputs!B12) -> 1710000 | G5: =Inputs!B6*(C5/D5)*F5 -> 3837500000 | H5: =Inputs!B7*C5*Inputs!B11 -> 76750000000 | I5: =Inputs!B8*B5 -> 0 | J5: =IF(D5>0,H5/D5,0) -> 224.4152 | K5: =IF(D5>0,I5/D5/12,0) -> 0 | L5: =((G5/MAX(F5,1))+J5)*(1+Inputs!B14) -> 2629.0241 | M5: =L5/E5 -> 2629.0241 | N5: =K5*12/E5 -> 0
A6: 1 | B6: =B5+G5+H5+I5 -> 22780587500000 | C6: =C5*(1+Inputs!B11)*(1+Inputs!B13) -> 31314000000000 | D6: =D5*(1+Inputs!B12) -> 343710000 | E6: =E5*(1+Inputs!B13) -> 1 | F6: =MAX(0,D6*Inputs!B12) -> 1718550 | G6: =Inputs!B6*(C6/D6)*F6 -> 3914250000 | H6: =Inputs!B7*C6*Inputs!B11 -> 78285000000 | I6: =Inputs!B8*B6 -> 0 | J6: =IF(D6>0,H6/D6,0) -> 227.76469 | K6: =IF(D6>0,I6/D6/12,0) -> 0 | L6: =(L5+J6)*(1+Inputs!B14) -> 3042.4801 | M6: =L6/E6 -> 3042.4801 | N6: =N5+K6*12/E6 -> 0
A7: 2 | B7: =B6+G6+H6+I6 -> 22862786750000 | C7: =C6*(1+Inputs!B11)*(1+Inputs!B13) -> 31940280000000 | D7: =D6*(1+Inputs!B12) -> 345428550 | E7: =E6*(1+Inputs!B13) -> 1 | F7: =MAX(0,D7*Inputs!B12) -> 1727142.8 | G7: =Inputs!B6*(C7/D7)*F7 -> 3992535000 | H7: =Inputs!B7*C7*Inputs!B11 -> 79850700000 | I7: =Inputs!B8*B7 -> 0 | J7: =IF(D7>0,H7/D7,0) -> 231.16416 | K7: =IF(D7>0,I7/D7/12,0) -> 0 | L7: =(L6+J7)*(1+Inputs!B14) -> 3486.4311 | M7: =L7/E7 -> 3486.4311 | N7: =N6+K7*12/E7 -> 0
A8: 3 | B8: =B7+G7+H7+I7 -> 22946629985000 | C8: =C7*(1+Inputs!B11)*(1+Inputs!B13) -> 32579085600000 | D8: =D7*(1+Inputs!B12) -> 3.4715569e+08 | E8: =E7*(1+Inputs!B13) -> 1 | F8: =MAX(0,D8*Inputs!B12) -> 1735778.5 | G8: =Inputs!B6*(C8/D8)*F8 -> 4072385700 | H8: =Inputs!B7*C8*Inputs!B11 -> 81447714000 | I8: =Inputs!B8*B8 -> 0 | J8: =IF(D8>0,H8/D8,0) -> 234.61437 | K8: =IF(D8>0,I8/D8/12,0) -> 0 | L8: =(L7+J8)*(1+Inputs!B14) -> 3962.9134 | M8: =L8/E8 -> 3962.9134 | N8: =N7+K8*12/E8 -> 0
A9: 4 | B9: =B8+G8+H8+I8 -> 23032150084700 | C9: =C8*(1+Inputs!B11)*(1+Inputs!B13) -> 33230667312000 | D9: =D8*(1+Inputs!B12) -> 3.4889147e+08 | E9: =E8*(1+Inputs!B13) -> 1 | F9: =MAX(0,D9*Inputs!B12) -> 1744457.4 | G9: =Inputs!B6*(C9/D9)*F9 -> 4153833414 | H9: =Inputs!B7*C9*Inputs!B11 -> 83076668280 | I9: =Inputs!B8*B9 -> 0 | J9: =IF(D9>0,H9/D9,0) -> 238.11608 | K9: =IF(D9>0,I9/D9/12,0) -> 0 | L9: =(L8+J9)*(1+Inputs!B14) -> 4474.0964 | M9: =L9/E9 -> 4474.0964 | N9: =N8+K9*12/E9 -> 0
A10: 5 | B10: =B9+G9+H9+I9 -> 23119380586394 | C10: =C9*(1+Inputs!B11)*(1+Inputs!B13) -> 33895280658240 | D10: =D9*(1+Inputs!B12) -> 3.5063593e+08 | E10: =E9*(1+Inputs!B13) -> 1 | F10: =MAX(0,D10*Inputs!B12) -> 1753179.6 | G10: =Inputs!B6*(C10/D10)*F10 -> 4.2369101e+09 | H10: =Inputs!B7*C10*Inputs!B11 -> 8.4738202e+10 | I10: =Inputs!B8*B10 -> 0 | J10: =IF(D10>0,H10/D10,0) -> 241.67005 | K10: =IF(D10>0,I10/D10/12,0) -> 0 | L10: =(L9+J10)*(1+Inputs!B14) -> 5022.2913 | M10: =L10/E10 -> 5022.2913 | N10: =N9+K10*12/E10 -> 0
A11: 6 | B11: =B10+G10+H10+I10 -> 2.3208356e+13 | C11: =C10*(1+Inputs!B11)*(1+Inputs!B13) -> 3.4573186e+13 | D11: =D10*(1+Inputs!B12) -> 3.5238911e+08 | E11: =E10*(1+Inputs!B13) -> 1 | F11: =MAX(0,D11*Inputs!B12) -> 1761945.5 | G11: =Inputs!B6*(C11/D11)*F11 -> 4.3216483e+09 | H11: =Inputs!B7*C11*Inputs!B11 -> 8.6432966e+10 | I11: =Inputs!B8*B11 -> 0 | J11: =IF(D11>0,H11/D11,0) -> 245.27706 | K11: =IF(D11>0,I11/D11/12,0) -> 0 | L11: =(L10+J11)*(1+Inputs!B14) -> 5609.9603 | M11: =L11/E11 -> 5609.9603 | N11: =N10+K11*12/E11 -> 0
A12: 7 | B12: =B11+G11+H11+I11 -> 2.329911e+13 | C12: =C11*(1+Inputs!B11)*(1+Inputs!B13) -> 3.526465e+13 | D12: =D11*(1+Inputs!B12) -> 3.5415105e+08 | E12: =E11*(1+Inputs!B13) -> 1 | F12: =MAX(0,D12*Inputs!B12) -> 1770755.3 | G12: =Inputs!B6*(C12/D12)*F12 -> 4.4080812e+09 | H12: =Inputs!B7*C12*Inputs!B11 -> 8.8161625e+10 | I12: =Inputs!B8*B12 -> 0 | J12: =IF(D12>0,H12/D12,0) -> 248.93792 | K12: =IF(D12>0,I12/D12/12,0) -> 0 | L12: =(L11+J12)*(1+Inputs!B14) -> 6239.7266 | M12: =L12/E12 -> 6239.7266 | N12: =N11+K12*12/E12 -> 0
A13: 8 | B13: =B12+G12+H12+I12 -> 23391680018326 | C13: =C12*(1+Inputs!B11)*(1+Inputs!B13) -> 3.5969943e+13 | D13: =D12*(1+Inputs!B12) -> 3.5592181e+08 | E13: =E12*(1+Inputs!B13) -> 1 | F13: =MAX(0,D13*Inputs!B12) -> 1779609 | G13: =Inputs!B6*(C13/D13)*F13 -> 4.4962429e+09 | H13: =Inputs!B7*C13*Inputs!B11 -> 8.9924857e+10 | I13: =Inputs!B8*B13 -> 0 | J13: =IF(D13>0,H13/D13,0) -> 252.65341 | K13: =IF(D13>0,I13/D13/12,0) -> 0 | L13: =(L12+J13)*(1+Inputs!B14) -> 6914.3847 | M13: =L13/E13 -> 6914.3847 | N13: =N12+K13*12/E13 -> 0
A14: 9 | B14: =B13+G13+H13+I13 -> 2.3486101e+13 | C14: =C13*(1+Inputs!B11)*(1+Inputs!B13) -> 3.6689342e+13 | D14: =D13*(1+Inputs!B12) -> 3.5770142e+08 | E14: =E13*(1+Inputs!B13) -> 1 | F14: =MAX(0,D14*Inputs!B12) -> 1788507.1 | G14: =Inputs!B6*(C14/D14)*F14 -> 4.5861677e+09 | H14: =Inputs!B7*C14*Inputs!B11 -> 9.1723355e+10 | I14: =Inputs!B8*B14 -> 0 | J14: =IF(D14>0,H14/D14,0) -> 256.42435 | K14: =IF(D14>0,I14/D14/12,0) -> 0 | L14: =(L13+J14)*(1+Inputs!B14) -> 7636.9117 | M14: =L14/E14 -> 7636.9117 | N14: =N13+K14*12/E14 -> 0
A15: 10 | B15: =B14+G14+H14+I14 -> 2.3582411e+13 | C15: =C14*(1+Inputs!B11)*(1+Inputs!B13) -> 3.7423129e+13 | D15: =D14*(1+Inputs!B12) -> 3.5948993e+08 | E15: =E14*(1+Inputs!B13) -> 1 | F15: =MAX(0,D15*Inputs!B12) -> 1797449.6 | G15: =Inputs!B6*(C15/D15)*F15 -> 4.6778911e+09 | H15: =Inputs!B7*C15*Inputs!B11 -> 9.3557822e+10 | I15: =Inputs!B8*B15 -> 0 | J15: =IF(D15>0,H15/D15,0) -> 260.25158 | K15: =IF(D15>0,I15/D15/12,0) -> 0 | L15: =(L14+J15)*(1+Inputs!B14) -> 8410.4789 | M15: =L15/E15 -> 8410.4789 | N15: =N14+K15*12/E15 -> 0
A16: 11 | B16: =B15+G15+H15+I15 -> 2.3680646e+13 | C16: =C15*(1+Inputs!B11)*(1+Inputs!B13) -> 3.8171591e+13 | D16: =D15*(1+Inputs!B12) -> 3.6128737e+08 | E16: =E15*(1+Inputs!B13) -> 1 | F16: =MAX(0,D16*Inputs!B12) -> 1806436.9 | G16: =Inputs!B6*(C16/D16)*F16 -> 4.7714489e+09 | H16: =Inputs!B7*C16*Inputs!B11 -> 9.5428978e+10 | I16: =Inputs!B8*B16 -> 0 | J16: =IF(D16>0,H16/D16,0) -> 264.13593 | K16: =IF(D16>0,I16/D16/12,0) -> 0 | L16: =(L15+J16)*(1+Inputs!B14) -> 9238.4648 | M16: =L16/E16 -> 9238.4648 | N16: =N15+K16*12/E16 -> 0
A17: 12 | B17: =B16+G16+H16+I16 -> 2.3780847e+13 | C17: =C16*(1+Inputs!B11)*(1+Inputs!B13) -> 3.8935023e+13 | D17: =D16*(1+Inputs!B12) -> 3.6309381e+08 | E17: =E16*(1+Inputs!B13) -> 1 | F17: =MAX(0,D17*Inputs!B12) -> 1815469.1 | G17: =Inputs!B6*(C17/D17)*F17 -> 4.8668779e+09 | H17: =Inputs!B7*C17*Inputs!B11 -> 9.7337558e+10 | I17: =Inputs!B8*B17 -> 0 | J17: =IF(D17>0,H17/D17,0) -> 268.07826 | K17: =IF(D17>0,I17/D17/12,0) -> 0 | L17: =(L16+J17)*(1+Inputs!B14) -> 10124.468 | M17: =L17/E17 -> 10124.468 | N17: =N16+K17*12/E17 -> 0
A18: 13 | B18: =B17+G17+H17+I17 -> 2.3883051e+13 | C18: =C17*(1+Inputs!B11)*(1+Inputs!B13) -> 3.9713724e+13 | D18: =D17*(1+Inputs!B12) -> 3.6490928e+08 | E18: =E17*(1+Inputs!B13) -> 1 | F18: =MAX(0,D18*Inputs!B12) -> 1824546.4 | G18: =Inputs!B6*(C18/D18)*F18 -> 4.9642154e+09 | H18: =Inputs!B7*C18*Inputs!B11 -> 9.9284309e+10 | I18: =Inputs!B8*B18 -> 0 | J18: =IF(D18>0,H18/D18,0) -> 272.07943 | K18: =IF(D18>0,I18/D18/12,0) -> 0 | L18: =(L17+J18)*(1+Inputs!B14) -> 11072.323 | M18: =L18/E18 -> 11072.323 | N18: =N17+K18*12/E18 -> 0
A19: 14 | B19: =B18+G18+H18+I18 -> 2.39873e+13 | C19: =C18*(1+Inputs!B11)*(1+Inputs!B13) -> 4.0507998e+13 | D19: =D18*(1+Inputs!B12) -> 3.6673383e+08 | E19: =E18*(1+Inputs!B13) -> 1 | F19: =MAX(0,D19*Inputs!B12) -> 1833669.1 | G19: =Inputs!B6*(C19/D19)*F19 -> 5.0634998e+09 | H19: =Inputs!B7*C19*Inputs!B11 -> 1.0127e+11 | I19: =Inputs!B8*B19 -> 0 | J19: =IF(D19>0,H19/D19,0) -> 276.14032 | K19: =IF(D19>0,I19/D19/12,0) -> 0 | L19: =(L18+J19)*(1+Inputs!B14) -> 12086.114 | M19: =L19/E19 -> 12086.114 | N19: =N18+K19*12/E19 -> 0
A20: 15 | B20: =B19+G19+H19+I19 -> 2.4093633e+13 | C20: =C19*(1+Inputs!B11)*(1+Inputs!B13) -> 4.1318158e+13 | D20: =D19*(1+Inputs!B12) -> 3.685675e+08 | E20: =E19*(1+Inputs!B13) -> 1 | F20: =MAX(0,D20*Inputs!B12) -> 1842837.5 | G20: =Inputs!B6*(C20/D20)*F20 -> 5.1647697e+09 | H20: =Inputs!B7*C20*Inputs!B11 -> 1.0329539e+11 | I20: =Inputs!B8*B20 -> 0 | J20: =IF(D20>0,H20/D20,0) -> 280.26181 | K20: =IF(D20>0,I20/D20/12,0) -> 0 | L20: =(L19+J20)*(1+Inputs!B14) -> 13170.19 | M20: =L20/E20 -> 13170.19 | N20: =N19+K20*12/E20 -> 0
A21: 16 | B21: =B20+G20+H20+I20 -> 2.4202093e+13 | C21: =C20*(1+Inputs!B11)*(1+Inputs!B13) -> 4.2144521e+13 | D21: =D20*(1+Inputs!B12) -> 3.7041033e+08 | E21: =E20*(1+Inputs!B13) -> 1 | F21: =MAX(0,D21*Inputs!B12) -> 1852051.7 | G21: =Inputs!B6*(C21/D21)*F21 -> 5.2680651e+09 | H21: =Inputs!B7*C21*Inputs!B11 -> 1.053613e+11 | I21: =Inputs!B8*B21 -> 0 | J21: =IF(D21>0,H21/D21,0) -> 284.44483 | K21: =IF(D21>0,I21/D21/12,0) -> 0 | L21: =(L20+J21)*(1+Inputs!B14) -> 14329.186 | M21: =L21/E21 -> 14329.186 | N21: =N20+K21*12/E21 -> 0
A22: 17 | B22: =B21+G21+H21+I21 -> 2.4312723e+13 | C22: =C21*(1+Inputs!B11)*(1+Inputs!B13) -> 4.2987412e+13 | D22: =D21*(1+Inputs!B12) -> 3.7226239e+08 | E22: =E21*(1+Inputs!B13) -> 1 | F22: =MAX(0,D22*Inputs!B12) -> 1861311.9 | G22: =Inputs!B6*(C22/D22)*F22 -> 5.3734264e+09 | H22: =Inputs!B7*C22*Inputs!B11 -> 1.0746853e+11 | I22: =Inputs!B8*B22 -> 0 | J22: =IF(D22>0,H22/D22,0) -> 288.69027 | K22: =IF(D22>0,I22/D22/12,0) -> 0 | L22: =(L21+J22)*(1+Inputs!B14) -> 15568.038 | M22: =L22/E22 -> 15568.038 | N22: =N21+K22*12/E22 -> 0
A23: 18 | B23: =B22+G22+H22+I22 -> 2.4425565e+13 | C23: =C22*(1+Inputs!B11)*(1+Inputs!B13) -> 4.384716e+13 | D23: =D22*(1+Inputs!B12) -> 3.741237e+08 | E23: =E22*(1+Inputs!B13) -> 1 | F23: =MAX(0,D23*Inputs!B12) -> 1870618.5 | G23: =Inputs!B6*(C23/D23)*F23 -> 5.480895e+09 | H23: =Inputs!B7*C23*Inputs!B11 -> 1.096179e+11 | I23: =Inputs!B8*B23 -> 0 | J23: =IF(D23>0,H23/D23,0) -> 292.99908 | K23: =IF(D23>0,I23/D23/12,0) -> 0 | L23: =(L22+J23)*(1+Inputs!B14) -> 16892.005 | M23: =L23/E23 -> 16892.005 | N23: =N22+K23*12/E23 -> 0
A24: 19 | B24: =B23+G23+H23+I23 -> 2.4540664e+13 | C24: =C23*(1+Inputs!B11)*(1+Inputs!B13) -> 4.4724103e+13 | D24: =D23*(1+Inputs!B12) -> 3.7599432e+08 | E24: =E23*(1+Inputs!B13) -> 1 | F24: =MAX(0,D24*Inputs!B12) -> 1879971.6 | G24: =Inputs!B6*(C24/D24)*F24 -> 5.5905129e+09 | H24: =Inputs!B7*C24*Inputs!B11 -> 1.1181026e+11 | I24: =Inputs!B8*B24 -> 0 | J24: =IF(D24>0,H24/D24,0) -> 297.3722 | K24: =IF(D24>0,I24/D24/12,0) -> 0 | L24: =(L23+J24)*(1+Inputs!B14) -> 18306.687 | M24: =L24/E24 -> 18306.687 | N24: =N23+K24*12/E24 -> 0
A25: 20 | B25: =B24+G24+H24+I24 -> 2.4658064e+13 | C25: =C24*(1+Inputs!B11)*(1+Inputs!B13) -> 4.5618585e+13 | D25: =D24*(1+Inputs!B12) -> 3.7787429e+08 | E25: =E24*(1+Inputs!B13) -> 1 | F25: =MAX(0,D25*Inputs!B12) -> 1889371.4 | G25: =Inputs!B6*(C25/D25)*F25 -> 5.7023231e+09 | H25: =Inputs!B7*C25*Inputs!B11 -> 1.1404646e+11 | I25: =Inputs!B8*B25 -> 0 | J25: =IF(D25>0,H25/D25,0) -> 301.81059 | K25: =IF(D25>0,I25/D25/12,0) -> 0 | L25: =(L24+J25)*(1+Inputs!B14) -> 19818.049 | M25: =L25/E25 -> 19818.049 | N25: =N24+K25*12/E25 -> 0
A26: 21 | B26: =B25+G25+H25+I25 -> 2.4777813e+13 | C26: =C25*(1+Inputs!B11)*(1+Inputs!B13) -> 4.6530957e+13 | D26: =D25*(1+Inputs!B12) -> 3.7976366e+08 | E26: =E25*(1+Inputs!B13) -> 1 | F26: =MAX(0,D26*Inputs!B12) -> 1898818.3 | G26: =Inputs!B6*(C26/D26)*F26 -> 5.8163696e+09 | H26: =Inputs!B7*C26*Inputs!B11 -> 1.1632739e+11 | I26: =Inputs!B8*B26 -> 0 | J26: =IF(D26>0,H26/D26,0) -> 306.31523 | K26: =IF(D26>0,I26/D26/12,0) -> 0 | L26: =(L25+J26)*(1+Inputs!B14) -> 21432.448 | M26: =L26/E26 -> 21432.448 | N26: =N25+K26*12/E26 -> 0
A27: 22 | B27: =B26+G26+H26+I26 -> 2.4899957e+13 | C27: =C26*(1+Inputs!B11)*(1+Inputs!B13) -> 4.7461576e+13 | D27: =D26*(1+Inputs!B12) -> 3.8166248e+08 | E27: =E26*(1+Inputs!B13) -> 1 | F27: =MAX(0,D27*Inputs!B12) -> 1908312.4 | G27: =Inputs!B6*(C27/D27)*F27 -> 5.932697e+09 | H27: =Inputs!B7*C27*Inputs!B11 -> 1.1865394e+11 | I27: =Inputs!B8*B27 -> 0 | J27: =IF(D27>0,H27/D27,0) -> 310.8871 | K27: =IF(D27>0,I27/D27/12,0) -> 0 | L27: =(L26+J27)*(1+Inputs!B14) -> 23156.652 | M27: =L27/E27 -> 23156.652 | N27: =N26+K27*12/E27 -> 0
A28: 23 | B28: =B27+G27+H27+I27 -> 2.5024543e+13 | C28: =C27*(1+Inputs!B11)*(1+Inputs!B13) -> 4.8410807e+13 | D28: =D27*(1+Inputs!B12) -> 3.8357079e+08 | E28: =E27*(1+Inputs!B13) -> 1 | F28: =MAX(0,D28*Inputs!B12) -> 1917853.9 | G28: =Inputs!B6*(C28/D28)*F28 -> 6.0513509e+09 | H28: =Inputs!B7*C28*Inputs!B11 -> 1.2102702e+11 | I28: =Inputs!B8*B28 -> 0 | J28: =IF(D28>0,H28/D28,0) -> 315.5272 | K28: =IF(D28>0,I28/D28/12,0) -> 0 | L28: =(L27+J28)*(1+Inputs!B14) -> 24997.871 | M28: =L28/E28 -> 24997.871 | N28: =N27+K28*12/E28 -> 0
A29: 24 | B29: =B28+G28+H28+I28 -> 2.5151622e+13 | C29: =C28*(1+Inputs!B11)*(1+Inputs!B13) -> 4.9379024e+13 | D29: =D28*(1+Inputs!B12) -> 3.8548864e+08 | E29: =E28*(1+Inputs!B13) -> 1 | F29: =MAX(0,D29*Inputs!B12) -> 1927443.2 | G29: =Inputs!B6*(C29/D29)*F29 -> 6.1723779e+09 | H29: =Inputs!B7*C29*Inputs!B11 -> 1.2344756e+11 | I29: =Inputs!B8*B29 -> 0 | J29: =IF(D29>0,H29/D29,0) -> 320.23656 | K29: =IF(D29>0,I29/D29/12,0) -> 0 | L29: =(L28+J29)*(1+Inputs!B14) -> 26963.785 | M29: =L29/E29 -> 26963.785 | N29: =N28+K29*12/E29 -> 0
A30: 25 | B30: =B29+G29+H29+I29 -> 2.5281242e+13 | C30: =C29*(1+Inputs!B11)*(1+Inputs!B13) -> 5.0366604e+13 | D30: =D29*(1+Inputs!B12) -> 3.8741609e+08 | E30: =E29*(1+Inputs!B13) -> 1 | F30: =MAX(0,D30*Inputs!B12) -> 1937080.4 | G30: =Inputs!B6*(C30/D30)*F30 -> 6.2958255e+09 | H30: =Inputs!B7*C30*Inputs!B11 -> 1.2591651e+11 | I30: =Inputs!B8*B30 -> 0 | J30: =IF(D30>0,H30/D30,0) -> 325.01621 | K30: =IF(D30>0,I30/D30/12,0) -> 0 | L30: =(L29+J30)*(1+Inputs!B14) -> 29062.573 | M30: =L30/E30 -> 29062.573 | N30: =N29+K30*12/E30 -> 0
A31: 26 | B31: =B30+G30+H30+I30 -> 2.5413454e+13 | C31: =C30*(1+Inputs!B11)*(1+Inputs!B13) -> 5.1373936e+13 | D31: =D30*(1+Inputs!B12) -> 3.8935317e+08 | E31: =E30*(1+Inputs!B13) -> 1 | F31: =MAX(0,D31*Inputs!B12) -> 1946765.8 | G31: =Inputs!B6*(C31/D31)*F31 -> 6.421742e+09 | H31: =Inputs!B7*C31*Inputs!B11 -> 1.2843484e+11 | I31: =Inputs!B8*B31 -> 0 | J31: =IF(D31>0,H31/D31,0) -> 329.8672 | K31: =IF(D31>0,I31/D31/12,0) -> 0 | L31: =(L30+J31)*(1+Inputs!B14) -> 31302.949 | M31: =L31/E31 -> 31302.949 | N31: =N30+K31*12/E31 -> 0
A32: 27 | B32: =B31+G31+H31+I31 -> 2.5548311e+13 | C32: =C31*(1+Inputs!B11)*(1+Inputs!B13) -> 52401414832882 | D32: =D31*(1+Inputs!B12) -> 3.9129993e+08 | E32: =E31*(1+Inputs!B13) -> 1 | F32: =MAX(0,D32*Inputs!B12) -> 1956499.7 | G32: =Inputs!B6*(C32/D32)*F32 -> 6.5501769e+09 | H32: =Inputs!B7*C32*Inputs!B11 -> 1.3100354e+11 | I32: =Inputs!B8*B32 -> 0 | J32: =IF(D32>0,H32/D32,0) -> 334.79059 | K32: =IF(D32>0,I32/D32/12,0) -> 0 | L32: =(L31+J32)*(1+Inputs!B14) -> 33694.193 | M32: =L32/E32 -> 33694.193 | N32: =N31+K32*12/E32 -> 0
A33: 28 | B33: =B32+G32+H32+I32 -> 2.5685864e+13 | C33: =C32*(1+Inputs!B11)*(1+Inputs!B13) -> 5.3449443e+13 | D33: =D32*(1+Inputs!B12) -> 3.9325643e+08 | E33: =E32*(1+Inputs!B13) -> 1 | F33: =MAX(0,D33*Inputs!B12) -> 1966282.2 | G33: =Inputs!B6*(C33/D33)*F33 -> 6.6811804e+09 | H33: =Inputs!B7*C33*Inputs!B11 -> 1.3362361e+11 | I33: =Inputs!B8*B33 -> 0 | J33: =IF(D33>0,H33/D33,0) -> 339.78747 | K33: =IF(D33>0,I33/D33/12,0) -> 0 | L33: =(L32+J33)*(1+Inputs!B14) -> 36246.189 | M33: =L33/E33 -> 36246.189 | N33: =N32+K33*12/E33 -> 0
A34: 29 | B34: =B33+G33+H33+I33 -> 2.5826169e+13 | C34: =C33*(1+Inputs!B11)*(1+Inputs!B13) -> 5.4518432e+13 | D34: =D33*(1+Inputs!B12) -> 3.9522271e+08 | E34: =E33*(1+Inputs!B13) -> 1 | F34: =MAX(0,D34*Inputs!B12) -> 1976113.6 | G34: =Inputs!B6*(C34/D34)*F34 -> 6.814804e+09 | H34: =Inputs!B7*C34*Inputs!B11 -> 1.3629608e+11 | I34: =Inputs!B8*B34 -> 0 | J34: =IF(D34>0,H34/D34,0) -> 344.85892 | K34: =IF(D34>0,I34/D34/12,0) -> 0 | L34: =(L33+J34)*(1+Inputs!B14) -> 38969.466 | M34: =L34/E34 -> 38969.466 | N34: =N33+K34*12/E34 -> 0
A35: 30 | B35: =B34+G34+H34+I34 -> 2.596928e+13 | C35: =C34*(1+Inputs!B11)*(1+Inputs!B13) -> 55608800631973 | D35: =D34*(1+Inputs!B12) -> 3.9719883e+08 | E35: =E34*(1+Inputs!B13) -> 1 | F35: =MAX(0,D35*Inputs!B12) -> 1985994.1 | G35: =Inputs!B6*(C35/D35)*F35 -> 6.9511001e+09 | H35: =Inputs!B7*C35*Inputs!B11 -> 1.39022e+11 | I35: =Inputs!B8*B35 -> 0 | J35: =IF(D35>0,H35/D35,0) -> 350.00607 | K35: =IF(D35>0,I35/D35/12,0) -> 0 | L35: =(L34+J35)*(1+Inputs!B14) -> 41875.237 | M35: =L35/E35 -> 41875.237 | N35: =N34+K35*12/E35 -> 0
A36: 31 | B36: =B35+G35+H35+I35 -> 2.6115253e+13 | C36: =C35*(1+Inputs!B11)*(1+Inputs!B13) -> 5.6720977e+13 | D36: =D35*(1+Inputs!B12) -> 3.9918482e+08 | E36: =E35*(1+Inputs!B13) -> 1 | F36: =MAX(0,D36*Inputs!B12) -> 1995924.1 | G36: =Inputs!B6*(C36/D36)*F36 -> 7.0901221e+09 | H36: =Inputs!B7*C36*Inputs!B11 -> 1.4180244e+11 | I36: =Inputs!B8*B36 -> 0 | J36: =IF(D36>0,H36/D36,0) -> 355.23004 | K36: =IF(D36>0,I36/D36/12,0) -> 0 | L36: =(L35+J36)*(1+Inputs!B14) -> 44975.448 | M36: =L36/E36 -> 44975.448 | N36: =N35+K36*12/E36 -> 0
A37: 32 | B37: =B36+G36+H36+I36 -> 2.6264146e+13 | C37: =C36*(1+Inputs!B11)*(1+Inputs!B13) -> 5.7855396e+13 | D37: =D36*(1+Inputs!B12) -> 4.0118075e+08 | E37: =E36*(1+Inputs!B13) -> 1 | F37: =MAX(0,D37*Inputs!B12) -> 2005903.7 | G37: =Inputs!B6*(C37/D37)*F37 -> 7.2319245e+09 | H37: =Inputs!B7*C37*Inputs!B11 -> 1.4463849e+11 | I37: =Inputs!B8*B37 -> 0 | J37: =IF(D37>0,H37/D37,0) -> 360.53198 | K37: =IF(D37>0,I37/D37/12,0) -> 0 | L37: =(L36+J37)*(1+Inputs!B14) -> 48282.819 | M37: =L37/E37 -> 48282.819 | N37: =N36+K37*12/E37 -> 0
A38: 33 | B38: =B37+G37+H37+I37 -> 2.6416016e+13 | C38: =C37*(1+Inputs!B11)*(1+Inputs!B13) -> 5.9012504e+13 | D38: =D37*(1+Inputs!B12) -> 4.0318665e+08 | E38: =E37*(1+Inputs!B13) -> 1 | F38: =MAX(0,D38*Inputs!B12) -> 2015933.3 | G38: =Inputs!B6*(C38/D38)*F38 -> 7.376563e+09 | H38: =Inputs!B7*C38*Inputs!B11 -> 1.4753126e+11 | I38: =Inputs!B8*B38 -> 0 | J38: =IF(D38>0,H38/D38,0) -> 365.91306 | K38: =IF(D38>0,I38/D38/12,0) -> 0 | L38: =(L37+J38)*(1+Inputs!B14) -> 51810.899 | M38: =L38/E38 -> 51810.899 | N38: =N37+K38*12/E38 -> 0
A39: 34 | B39: =B38+G38+H38+I38 -> 2.6570924e+13 | C39: =C38*(1+Inputs!B11)*(1+Inputs!B13) -> 6.0192754e+13 | D39: =D38*(1+Inputs!B12) -> 4.0520258e+08 | E39: =E38*(1+Inputs!B13) -> 1 | F39: =MAX(0,D39*Inputs!B12) -> 2026012.9 | G39: =Inputs!B6*(C39/D39)*F39 -> 7.5240943e+09 | H39: =Inputs!B7*C39*Inputs!B11 -> 1.5048189e+11 | I39: =Inputs!B8*B39 -> 0 | J39: =IF(D39>0,H39/D39,0) -> 371.37445 | K39: =IF(D39>0,I39/D39/12,0) -> 0 | L39: =(L38+J39)*(1+Inputs!B14) -> 55574.121 | M39: =L39/E39 -> 55574.121 | N39: =N38+K39*12/E39 -> 0
A40: 35 | B40: =B39+G39+H39+I39 -> 2.672893e+13 | C40: =C39*(1+Inputs!B11)*(1+Inputs!B13) -> 6.1396609e+13 | D40: =D39*(1+Inputs!B12) -> 4.072286e+08 | E40: =E39*(1+Inputs!B13) -> 1 | F40: =MAX(0,D40*Inputs!B12) -> 2036143 | G40: =Inputs!B6*(C40/D40)*F40 -> 7.6745762e+09 | H40: =Inputs!B7*C40*Inputs!B11 -> 1.5349152e+11 | I40: =Inputs!B8*B40 -> 0 | J40: =IF(D40>0,H40/D40,0) -> 376.91735 | K40: =IF(D40>0,I40/D40/12,0) -> 0 | L40: =(L39+J40)*(1+Inputs!B14) -> 59587.856 | M40: =L40/E40 -> 59587.856 | N40: =N39+K40*12/E40 -> 0
A41: 36 | B41: =B40+G40+H40+I40 -> 2.6890096e+13 | C41: =C40*(1+Inputs!B11)*(1+Inputs!B13) -> 6.2624541e+13 | D41: =D40*(1+Inputs!B12) -> 4.0926474e+08 | E41: =E40*(1+Inputs!B13) -> 1 | F41: =MAX(0,D41*Inputs!B12) -> 2046323.7 | G41: =Inputs!B6*(C41/D41)*F41 -> 7.8280677e+09 | H41: =Inputs!B7*C41*Inputs!B11 -> 1.5656135e+11 | I41: =Inputs!B8*B41 -> 0 | J41: =IF(D41>0,H41/D41,0) -> 382.54298 | K41: =IF(D41>0,I41/D41/12,0) -> 0 | L41: =(L40+J41)*(1+Inputs!B14) -> 63868.475 | M41: =L41/E41 -> 63868.475 | N41: =N40+K41*12/E41 -> 0
...

Sheet Summary
A1: Headline outcomes at horizon
A2: Pulled live from Projection sheet using the Inputs!horizon value.
A4: Output | B4: Value | C4: Definition
A5: Stable Floor at horizon (real $) | B5: =INDEX(Projection!M5:M85,MATCH(Inputs!B20,Projection!A5:A85,0)) -> 435261.3 | C5: Locked equity for one citizen, in launch-year purchasing power.
A6: Annual real income at horizon | B6: =INDEX(Projection!M5:M85,MATCH(Inputs!B20,Projection!A5:A85,0))*Inputs!B21 -> 17410.452 | C6: Stable Floor × withdrawal rate.
A7: K3 monthly dividend, year 1 | B7: =INDEX(Projection!K5:K85,2) -> 0 | C7: K3 spendable dividend per citizen, first year.
A8: K3 cumulative lifetime (real $) | B8: =INDEX(Projection!N5:N85,MATCH(Inputs!B20,Projection!A5:A85,0)) -> 0 | C8: Total dividend received by horizon, today dollars.
A9: Total real wealth at horizon | B9: =INDEX(Projection!M5:M85,MATCH(Inputs!B20,Projection!A5:A85,0))+INDEX(Projection!N5:N85,MATCH(Inputs!B20,Projection!A5:A85,0)) -> 435261.3 | C9: Stable Floor + cumulative K3 (both real $).
A10: Total issuance / M2, year 1 | B10: =(INDEX(Projection!G5:G85,2)+INDEX(Projection!H5:H85,2)+INDEX(Projection!I5:I85,2))/INDEX(Projection!B5:B85,2) -> 0.0036083025 | C10: Annual K1+K2+K3 as fraction of money supply.
A11: Total issuance / GDP, year 1 | B11: =(INDEX(Projection!G5:G85,2)+INDEX(Projection!H5:H85,2)+INDEX(Projection!I5:I85,2))/INDEX(Projection!C5:C85,2) -> 0.002625 | C11: Annual K1+K2+K3 as fraction of GDP.
A12: M2 at horizon ($) | B12: =INDEX(Projection!B5:B85,MATCH(Inputs!B20,Projection!A5:A85,0)) -> 3.3267129e+13 | C12: Final money supply.
A13: GDP at horizon ($) | B13: =INDEX(Projection!C5:C85,MATCH(Inputs!B20,Projection!A5:A85,0)) -> 111211459419972 | C13: Final nominal GDP.
A14: Population at horizon | B14: =INDEX(Projection!D5:D85,MATCH(Inputs!B20,Projection!A5:A85,0)) -> 4.7295533e+08 | C14: Final citizen count.
A15: CPI index at horizon | B15: =INDEX(Projection!E5:E85,MATCH(Inputs!B20,Projection!A5:A85,0)) -> 1 | C15: Price level relative to launch (1.0 = no change).

Sheet Comparison
A1: How does the Citizens Standard compare to real-world outcomes?
A2: Each column shows what one citizen actually receives under that system, using real-world median data — not theoretical maximums. Toggle the scenario in the yellow cell below to switch between median, average, and post-SS-cut outcomes.
A4: Real-world data anchors
A5: Median 401(k) at age 55-64 | B5: 87571 | C5: Vanguard 2025 — half of Americans have less
A6: Average 401(k) at age 55-64 | B6: 244750 | C6: Vanguard 2025 — skewed by top earners
A7: Average SS benefit (annual) | B7: 24953 | C7: SSA Mar 2026 — $2,079.49/mo × 12
A8: SS benefit cut after trust depletion | B8: 0.23 | C8: 2025 SSA Trustees Report — projected ~2034
A9: Alaska PFD (annual) | B9: 1700 | C9: Alaska DOR — recent average
A10: UBI proposal (monthly) | B10: 1000 | C10: Adjustable — common UBI proposal level
A11: MMT jobs guarantee wage | B11: 31200 | C11: $15/hr × 2080 hrs
A13: Scenario | B13: median | C13: Type: median, average, or ss-cut
A15: Lifetime delivery to one citizen, age 0 → horizon
A16: Metric | B16: Citizens Standard | C16: Fed status quo + SS | D16: Chicago Plan | E16: Friedman k-rule | F16: Bitcoin / fixed supply | G16: Alaska PFD (US-scale) | H16: UBI (tax-funded) | I16: MMT + jobs guarantee
A17: Wealth at horizon (real $) | B17: =Summary!B5 -> 435261.3 | C17: =IF($B$13="average",$B$6,$B$5) -> 87571 | D17: =IF($B$13="average",$B$6,$B$5) -> 87571 | E17: =IF($B$13="average",$B$6,$B$5) -> 87571 | F17: =IF($B$13="average",$B$6,$B$5) -> 87571 | G17: =IF($B$13="average",$B$6,$B$5) -> 87571 | H17: =IF($B$13="average",$B$6,$B$5) -> 87571 | I17: =IF($B$13="average",$B$6,$B$5) -> 87571
A18: Lifetime cash transfers (real $) | B18: =Summary!B8 -> 0 | C18: 0 | D18: 0 | E18: 0 | F18: 0 | G18: =$B$9*Inputs!B20 -> 110500 | H18: =$B$10*12*Inputs!B20 -> 780000 | I18: =$B$11*43 -> 1341600
A19: Annual retirement income | B19: =Summary!B5*Inputs!B21+Projection!K5*12 -> 17410.452 | C19: =IF($B$13="average",$B$6,$B$5)*Inputs!B21+IF($B$13="ss-cut",$B$7*(1-$B$8),$B$7) -> 28455.84 | D19: =IF($B$13="average",$B$6,$B$5)*Inputs!B21 -> 3502.84 | E19: =IF($B$13="average",$B$6,$B$5)*Inputs!B21 -> 3502.84 | F19: =IF($B$13="average",$B$6,$B$5)*Inputs!B21 -> 3502.84 | G19: =IF($B$13="average",$B$6,$B$5)*Inputs!B21+$B$9 -> 5202.84 | H19: =IF($B$13="average",$B$6,$B$5)*Inputs!B21+$B$10*12 -> 15502.84 | I19: =IF($B$13="average",$B$6,$B$5)*Inputs!B21 -> 3502.84
A21: Structural properties
A22: Rules-based (no committee discretion) | B22: ✓ | C22: ✗ | D22: ✓ | E22: ✓ | F22: ✓ | G22: partial | H22: ✗ | I22: ✗
A23: Per-citizen distribution | B23: ✓ | C23: ✗ | D23: ✗ | E23: ✗ | F23: ✗ | G23: ✓ | H23: ✓ | I23: partial
A24: Real-growth response | B24: ✓ | C24: partial | D24: ✗ | E24: ✗ | F24: ✗ | G24: partial | H24: ✗ | I24: ✓
A25: Crisis response capacity | B25: bounded | C25: unbounded | D25: limited | E25: none | F25: none | G25: limited | H25: limited | I25: unbounded
A26: Constitutional / hard to revoke | B26: ✓ | C26: ✗ | D26: ✗ | E26: ✗ | F26: ✓ | G26: ✗ | H26: ✗ | I26: ✗
A27: Funded by | B27: Seigniorage | C27: Mixed | D27: Govt seigniorage | E27: Fed seigniorage | F27: Mining rewards | G27: Resource royalty | H27: Taxation | I27: Treasury seigniorage
A29: Honest caveats
A30: Citizens Standard | B30: Single-cohort projection with constant rates. K3 modeled as flat % of M2 (not full price-level path targeting). Real values use your CPI input.
A31: Fed status quo | B31: Uses real-world median 401(k) balance ($87,571 at 55-64, Vanguard 2025) — what Americans actually retire with, not what disciplined savers theoretically could. Add SS at scenario-appropriate level.
A32: Chicago Plan | B32: 1933 proposal eliminated bank money creation but never specified seigniorage distribution. Citizens still rely on personal savings.
A33: Friedman k-rule | B33: Specified rate of monetary expansion but never the distribution channel. Nothing reaches citizens directly.
A34: Bitcoin | B34: Treated as savings vehicle with same equity-equivalent return for fair comparison. Real Bitcoin returns have been wildly volatile.
A35: Alaska PFD | B35: Modeled at $1,700/yr default. Real Alaska PFD funded by oil royalties, not seigniorage.
A36: UBI | B36: Funded by taxation, not money creation. Fiscal sustainability question is real and unresolved at scale.
A37: MMT | B37: Assumes citizen employed in jobs guarantee for full 43-year working life. Inflation control depends on tax policy responding correctly to demand pressure.
A39: Data sources
A40: Vanguard, How America Saves 2025: median 401(k) at 55-64 = $87,571; average = $244,750.
A41: Social Security Administration, Monthly Statistical Snapshot, March 2026: average retired-worker benefit = $2,079.49/month.
A42: 2025 SSA Trustees Report: OASI trust fund projected to deplete ~2034; benefits cut to ~77-81% of scheduled.
A43: SSA/CBO replacement rate analyses: ~37-42% for average earner.
A44: Alaska Department of Revenue: PFD historical range $1,200-$3,300/year.

Sheet Mode Presets
A1: Mode reference values from the paper
A2: Copy these into the Inputs sheet to replay any of the three constitutional Modes.
A3: What each Mode optimizes
A4: Parameter | B4: Mode A — Maximum wealth (deflation) | C4: Mode B — Stable prices (neutral) | D4: Mode C — Monthly dividend (inflation) | E4: Notes
A5: K1 — Citizenship | B5: 2.5% | C5: 2.5% | D5: 2.5% | E5: Identical across modes — anchor the citizenship endowment.
A6: K2 — Growth | B6: 12.5% | C6: 84% | D6: 12.5% | E6: Mode B raises K2 share to absorb full real-growth issuance.
A7: K3 — Dividend | B7: 0% | C7: 0% | D7: ~4.0% | E7: Mode C only. Calibrated by price-level path targeting.
A8: CPI target | B8: -1.6% | C8: 0% | D8: +2.0% | E8: The defining macro outcome of each mode.
A9: Stable Floor at 65 (real) | B9: $1.7M | C9: $2.6M | D9: $145K | E9: Mode A wins on long-run wealth; Mode C trades it for dividends.
A10: Annual real income at 65 | B10: $68K | C10: $105K | D10: $5.8K + K3 | E10: 4% withdrawal rate, plus ongoing K3 in Mode C.
A11: K3 monthly dividend, yr 1 | B11: $0 | C11: $0 | D11: $208 | E11: Per citizen, rises with M2 over time.
A12: Total issuance / M2 | B12: ~0.35% | C12: ~2.5% | D12: ~4.1% | E12: Annual issuance as fraction of money supply.
A13: Constitutional change | B13: Tier 2: 67% supermajority + 90-day deliberation | E13: Modes do NOT auto-rotate. Selection is a constitutional act.
A15: Mode philosophy
A16: Mode A | B16: Maximum lifetime wealth via gentle deflation. No monthly dividend. K2 contracts to ~12.5% so most of real growth flows to falling prices rather than expanding M2. The Stable Floor compounds aggressively because purchasing power rises over time. Best for retirement-focused societies.
A17: Mode B | B17: Price stability. K2 expanded to ~84% so circulating money matches real growth exactly — no monetary inflation, no monetary deflation. Highest possible Stable Floor wealth without dividend. Default neutral mode.
A18: Mode C | B18: Monthly citizen dividend at the cost of lower locked wealth. K3 activates (~4% of M2) and is calibrated by price-level path targeting to hit ~2% inflation. Citizens get ~$208/month at launch (rising over time) plus a smaller Stable Floor.

Sheet How It Works
A1: Formula reference and assumptions — Interactive Model Builder
A3: Architecture
A4: Two pools | B4: Circulating money (M2) and the Citizen Equity Stake (Stable Floor). They intersect only at K1/K2 issuance and at retirement withdrawals.
A5: Three channels | B5: K1 fires once per new citizen. K2 fires every year. K3 fires monthly (active in Mode C).
A7: K1 formula | B7: K1 total = K1_share × (GDP / population) × births_this_year
A8: K2 formula | B8: K2 total = K2_share × (GDP × real_growth_rate)
A9: K3 formula | B9: K3 total = K3_share × M2 (paper uses price-level path targeting; this engine uses a flat % of M2 as the simplified equivalent)
A11: Stable Floor | B11: For our representative cohort (born at t=0): floor compounds at the equity return rate. K1 is deposited once at birth; K2 is deposited every year. Both lock until retirement.
A12: Real values | B12: CPI index starts at 1.0 and grows at the CPI inflation rate. Real value = nominal / CPI index.
A13: K3 distribution | B13: K3 is unlocked, immediately spendable, deposited monthly into citizen transaction accounts.
A15: Simplifications | B15: This engine is a single-cohort projection with constant rates. The full paper models stochastic returns, mode transitions, sequence-of-returns risk, and emergency tools. Use this for intuition, not policy calibration.
A16: Equity return | B16: Treated as nominal in this model. If you want real returns, set CPI=0 and the equity return is automatically real.
A17: Births formula | B17: Births = pop × pop_growth_rate. Real demographics are more complex; this is a proxy.
A18: Mode C K3 calibration | B18: The paper calibrates K3 dynamically to close the cumulative CPI gap. Setting K3 to a flat ~4% of M2 reproduces the launch-year value but not the dynamic behavior.
... A25: Comparison sheet | B25: Side-by-side view of Citizens Standard against 7 alternative systems (Fed status quo, Chicago Plan, Friedman k-rule, Bitcoin, Alaska PFD, UBI, MMT). Adjust the comparison-specific assumptions at the top of that sheet.
