Workbook

Sheet Inputs
A1: Citizens Standard — Interactive Model Builder
A2: Adjust the yellow cells; everything else recalculates. Mode A = maximum wealth (deflation). Mode B = stable prices. Mode C = monthly dividend (inflation). See Mode Presets sheet for reference values.
A4: Mode preset
A5: Mode (A / B / C / custom) | B5: B
A6: Active configuration | B6: =IF(B5="A","Mode A — Maximum wealth via deflation",IF(B5="B","Mode B — Stable prices",IF(B5="C","Mode C — Monthly dividend",IF(B5="custom","Custom (manual values below)","⚠ Type A, B, C, or custom")))) -> Mode B — Stable prices
A7: Parameter | B7: Value | C7: Unit | D7: Notes
A8: Issuance channels (K-values)
A9: K1 — Citizenship endowment | B9: 0.025 | C9: % of GDP/capita per new citizen | D9: Mode A: 2.5%. Constitutional ceiling 5% (normal), 7.5% emergency.
A10: K2 — Growth dividend | B10: =IF($B$5="A",0.125,IF($B$5="B",0.84,IF($B$5="C",0.125,0.84))) -> 0.84
A11: K3 — Citizen dividend | B11: =IF($B$5="A",0,IF($B$5="B",0,IF($B$5="C",0.04,0))) -> 0 | C11: % of M2 issued annually as monthly dividend | D11: Mode A & B: 0%. Mode C: ~4% (calibrated to hit 2% inflation target).
A13: Macro environment
A14: Real GDP growth rate | B14: 0.02 | C14: annual | D14: Long-run US average ~2%. Drops in recessions.
A15: Population growth rate | B15: 0.005 | C15: annual | D15: US recent: 0.5%. Sets new-citizen K1 deposits.
A16: CPI inflation rate | B16: =IF($B$5="A",-0.016,IF($B$5="B",0,IF($B$5="C",0.02,0))) -> 0
A17: Equity index real return | B17: 0.065 | C17: annual | D17: Stable Floor compounds at this rate (after-inflation if CPI=0; nominal otherwise — see notes).
A19: Launch conditions (year 0)
A20: M2 money supply | B20: 22700000000000 | C20: dollars | D20: US M2 in launch year. Determines circulating pool size.
A21: Nominal GDP | B21: 30700000000000 | C21: dollars | D21: US GDP in launch year.
A22: Population | B22: 342000000 | C22: citizens | D22: Verified citizens at launch.
A23: Projection horizon | B23: 65 | C23: years | D23: Cohort tracked from age 0 to this age.
A24: Withdrawal rate at horizon | B24: 0.04 | C24: % of Stable Floor | D24: Conventional 4% safe withdrawal rate.

Sheet Projection
A1: Year-by-year simulation
A2: All values computed from Inputs. Black text = formulas. Do not edit.
A4: Year | B4: M2 ($) | C4: GDP ($) | D4: Population | E4: CPI index | F4: Births | G4: K1 total ($) | H4: K2 total ($) | I4: K3 total ($) | J4: K2 / citizen | K4: K3 monthly / citizen | L4: Cohort floor (nominal $) | M4: Cohort floor (real $) | N4: Cohort K3 cumulative (real $)
A5: 0 | B5: =Inputs!B20 -> 22700000000000 | C5: =Inputs!B21 -> 30700000000000 | D5: =Inputs!B22 -> 342000000 | E5: 1 | F5: =MAX(0,D5*Inputs!B15) -> 1710000 | G5: =Inputs!B9*(C5/D5)*F5 -> 3837500000 | H5: =Inputs!B10*C5*Inputs!B14 -> 515760000000 | I5: =Inputs!B11*B5 -> 0 | J5: =IF(D5>0,H5/D5,0) -> 1508.0702 | K5: =IF(D5>0,I5/D5/12,0) -> 0 | L5: =((G5/MAX(F5,1))+J5)*(1+Inputs!B17) -> 3996.1167 | M5: =L5/E5 -> 3996.1167 | N5: =K5*12/E5 -> 0
A6: 1 | B6: =B5+G5+H5+I5 -> 23219597500000 | C6: =C5*(1+Inputs!B14)*(1+Inputs!B16) -> 31314000000000 | D6: =D5*(1+Inputs!B15) -> 343710000 | E6: =E5*(1+Inputs!B16) -> 1 | F6: =MAX(0,D6*Inputs!B15) -> 1718550 | G6: =Inputs!B9*(C6/D6)*F6 -> 3914250000 | H6: =Inputs!B10*C6*Inputs!B14 -> 526075200000 | I6: =Inputs!B11*B6 -> 0 | J6: =IF(D6>0,H6/D6,0) -> 1530.5787 | K6: =IF(D6>0,I6/D6/12,0) -> 0 | L6: =(L5+J6)*(1+Inputs!B17) -> 5885.9306 | M6: =L6/E6 -> 5885.9306 | N6: =N5+K6*12/E6 -> 0
A7: 2 | B7: =B6+G6+H6+I6 -> 23749586950000 | C7: =C6*(1+Inputs!B14)*(1+Inputs!B16) -> 31940280000000 | D7: =D6*(1+Inputs!B15) -> 345428550 | E7: =E6*(1+Inputs!B16) -> 1 | F7: =MAX(0,D7*Inputs!B15) -> 1727142.8 | G7: =Inputs!B9*(C7/D7)*F7 -> 3992535000 | H7: =Inputs!B10*C7*Inputs!B14 -> 536596704000 | I7: =Inputs!B11*B7 -> 0 | J7: =IF(D7>0,H7/D7,0) -> 1553.4231 | K7: =IF(D7>0,I7/D7/12,0) -> 0 | L7: =(L6+J7)*(1+Inputs!B17) -> 7922.9117 | M7: =L7/E7 -> 7922.9117 | N7: =N6+K7*12/E7 -> 0
A8: 3 | B8: =B7+G7+H7+I7 -> 24290176189000 | C8: =C7*(1+Inputs!B14)*(1+Inputs!B16) -> 32579085600000 | D8: =D7*(1+Inputs!B15) -> 3.4715569e+08 | E8: =E7*(1+Inputs!B16) -> 1 | F8: =MAX(0,D8*Inputs!B15) -> 1735778.5 | G8: =Inputs!B9*(C8/D8)*F8 -> 4072385700 | H8: =Inputs!B10*C8*Inputs!B14 -> 547328638080 | I8: =Inputs!B11*B8 -> 0 | J8: =IF(D8>0,H8/D8,0) -> 1576.6086 | K8: =IF(D8>0,I8/D8/12,0) -> 0 | L8: =(L7+J8)*(1+Inputs!B17) -> 10116.989 | M8: =L8/E8 -> 10116.989 | N8: =N7+K8*12/E8 -> 0
A9: 4 | B9: =B8+G8+H8+I8 -> 24841577212780 | C9: =C8*(1+Inputs!B14)*(1+Inputs!B16) -> 33230667312000 | D9: =D8*(1+Inputs!B15) -> 3.4889147e+08 | E9: =E8*(1+Inputs!B16) -> 1 | F9: =MAX(0,D9*Inputs!B15) -> 1744457.4 | G9: =Inputs!B9*(C9/D9)*F9 -> 4153833414 | H9: =Inputs!B10*C9*Inputs!B14 -> 5.5827521e+11 | I9: =Inputs!B11*B9 -> 0 | J9: =IF(D9>0,H9/D9,0) -> 1600.14 | K9: =IF(D9>0,I9/D9/12,0) -> 0 | L9: =(L8+J9)*(1+Inputs!B17) -> 12478.742 | M9: =L9/E9 -> 12478.742 | N9: =N8+K9*12/E9 -> 0
A10: 5 | B10: =B9+G9+H9+I9 -> 2.5404006e+13 | C10: =C9*(1+Inputs!B14)*(1+Inputs!B16) -> 33895280658240 | D10: =D9*(1+Inputs!B15) -> 3.5063593e+08 | E10: =E9*(1+Inputs!B16) -> 1 | F10: =MAX(0,D10*Inputs!B15) -> 1753179.6 | G10: =Inputs!B9*(C10/D10)*F10 -> 4.2369101e+09 | H10: =Inputs!B10*C10*Inputs!B14 -> 5.6944072e+11 | I10: =Inputs!B11*B10 -> 0 | J10: =IF(D10>0,H10/D10,0) -> 1624.0227 | K10: =IF(D10>0,I10/D10/12,0) -> 0 | L10: =(L9+J10)*(1+Inputs!B17) -> 15019.445 | M10: =L10/E10 -> 15019.445 | N10: =N9+K10*12/E10 -> 0
A11: 6 | B11: =B10+G10+H10+I10 -> 2.5977684e+13 | C11: =C10*(1+Inputs!B14)*(1+Inputs!B16) -> 3.4573186e+13 | D11: =D10*(1+Inputs!B15) -> 3.5238911e+08 | E11: =E10*(1+Inputs!B16) -> 1 | F11: =MAX(0,D11*Inputs!B15) -> 1761945.5 | G11: =Inputs!B9*(C11/D11)*F11 -> 4.3216483e+09 | H11: =Inputs!B10*C11*Inputs!B14 -> 5.8082953e+11 | I11: =Inputs!B11*B11 -> 0 | J11: =IF(D11>0,H11/D11,0) -> 1648.2619 | K11: =IF(D11>0,I11/D11/12,0) -> 0 | L11: =(L10+J11)*(1+Inputs!B17) -> 17751.108 | M11: =L11/E11 -> 17751.108 | N11: =N10+K11*12/E11 -> 0
A12: 7 | B12: =B11+G11+H11+I11 -> 2.6562835e+13 | C12: =C11*(1+Inputs!B14)*(1+Inputs!B16) -> 3.526465e+13 | D12: =D11*(1+Inputs!B15) -> 3.5415105e+08 | E12: =E11*(1+Inputs!B16) -> 1 | F12: =MAX(0,D12*Inputs!B15) -> 1770755.3 | G12: =Inputs!B9*(C12/D12)*F12 -> 4.4080812e+09 | H12: =Inputs!B10*C12*Inputs!B14 -> 5.9244612e+11 | I12: =Inputs!B11*B12 -> 0 | J12: =IF(D12>0,H12/D12,0) -> 1672.8628 | K12: =IF(D12>0,I12/D12/12,0) -> 0 | L12: =(L11+J12)*(1+Inputs!B17) -> 20686.529 | M12: =L12/E12 -> 20686.529 | N12: =N11+K12*12/E12 -> 0
A13: 8 | B13: =B12+G12+H12+I12 -> 2.7159689e+13 | C13: =C12*(1+Inputs!B14)*(1+Inputs!B16) -> 3.5969943e+13 | D13: =D12*(1+Inputs!B15) -> 3.5592181e+08 | E13: =E12*(1+Inputs!B16) -> 1 | F13: =MAX(0,D13*Inputs!B15) -> 1779609 | G13: =Inputs!B9*(C13/D13)*F13 -> 4.4962429e+09 | H13: =Inputs!B10*C13*Inputs!B14 -> 6.0429504e+11 | I13: =Inputs!B11*B13 -> 0 | J13: =IF(D13>0,H13/D13,0) -> 1697.8309 | K13: =IF(D13>0,I13/D13/12,0) -> 0 | L13: =(L12+J13)*(1+Inputs!B17) -> 23839.343 | M13: =L13/E13 -> 23839.343 | N13: =N12+K13*12/E13 -> 0
A14: 9 | B14: =B13+G13+H13+I13 -> 2.7768481e+13 | C14: =C13*(1+Inputs!B14)*(1+Inputs!B16) -> 3.6689342e+13 | D14: =D13*(1+Inputs!B15) -> 3.5770142e+08 | E14: =E13*(1+Inputs!B16) -> 1 | F14: =MAX(0,D14*Inputs!B15) -> 1788507.1 | G14: =Inputs!B9*(C14/D14)*F14 -> 4.5861677e+09 | H14: =Inputs!B10*C14*Inputs!B14 -> 6.1638094e+11 | I14: =Inputs!B11*B14 -> 0 | J14: =IF(D14>0,H14/D14,0) -> 1723.1717 | K14: =IF(D14>0,I14/D14/12,0) -> 0 | L14: =(L13+J14)*(1+Inputs!B17) -> 27224.078 | M14: =L14/E14 -> 27224.078 | N14: =N13+K14*12/E14 -> 0
A15: 10 | B15: =B14+G14+H14+I14 -> 2.8389448e+13 | C15: =C14*(1+Inputs!B14)*(1+Inputs!B16) -> 3.7423129e+13 | D15: =D14*(1+Inputs!B15) -> 3.5948993e+08 | E15: =E14*(1+Inputs!B16) -> 1 | F15: =MAX(0,D15*Inputs!B15) -> 1797449.6 | G15: =Inputs!B9*(C15/D15)*F15 -> 4.6778911e+09 | H15: =Inputs!B10*C15*Inputs!B14 -> 6.2870856e+11 | I15: =Inputs!B11*B15 -> 0 | J15: =IF(D15>0,H15/D15,0) -> 1748.8906 | K15: =IF(D15>0,I15/D15/12,0) -> 0 | L15: =(L14+J15)*(1+Inputs!B17) -> 30856.212 | M15: =L15/E15 -> 30856.212 | N15: =N14+K15*12/E15 -> 0
A16: 11 | B16: =B15+G15+H15+I15 -> 2.9022834e+13 | C16: =C15*(1+Inputs!B14)*(1+Inputs!B16) -> 3.8171591e+13 | D16: =D15*(1+Inputs!B15) -> 3.6128737e+08 | E16: =E15*(1+Inputs!B16) -> 1 | F16: =MAX(0,D16*Inputs!B15) -> 1806436.9 | G16: =Inputs!B9*(C16/D16)*F16 -> 4.7714489e+09 | H16: =Inputs!B10*C16*Inputs!B14 -> 6.4128273e+11 | I16: =Inputs!B11*B16 -> 0 | J16: =IF(D16>0,H16/D16,0) -> 1774.9935 | K16: =IF(D16>0,I16/D16/12,0) -> 0 | L16: =(L15+J16)*(1+Inputs!B17) -> 34752.233 | M16: =L16/E16 -> 34752.233 | N16: =N15+K16*12/E16 -> 0
A17: 12 | B17: =B16+G16+H16+I16 -> 2.9668888e+13 | C17: =C16*(1+Inputs!B14)*(1+Inputs!B16) -> 3.8935023e+13 | D17: =D16*(1+Inputs!B15) -> 3.6309381e+08 | E17: =E16*(1+Inputs!B16) -> 1 | F17: =MAX(0,D17*Inputs!B15) -> 1815469.1 | G17: =Inputs!B9*(C17/D17)*F17 -> 4.8668779e+09 | H17: =Inputs!B10*C17*Inputs!B14 -> 6.5410839e+11 | I17: =Inputs!B11*B17 -> 0 | J17: =IF(D17>0,H17/D17,0) -> 1801.4859 | K17: =IF(D17>0,I17/D17/12,0) -> 0 | L17: =(L16+J17)*(1+Inputs!B17) -> 38929.711 | M17: =L17/E17 -> 38929.711 | N17: =N16+K17*12/E17 -> 0
A18: 13 | B18: =B17+G17+H17+I17 -> 3.0327864e+13 | C18: =C17*(1+Inputs!B14)*(1+Inputs!B16) -> 3.9713724e+13 | D18: =D17*(1+Inputs!B15) -> 3.6490928e+08 | E18: =E17*(1+Inputs!B16) -> 1 | F18: =MAX(0,D18*Inputs!B15) -> 1824546.4 | G18: =Inputs!B9*(C18/D18)*F18 -> 4.9642154e+09 | H18: =Inputs!B10*C18*Inputs!B14 -> 6.6719056e+11 | I18: =Inputs!B11*B18 -> 0 | J18: =IF(D18>0,H18/D18,0) -> 1828.3738 | K18: =IF(D18>0,I18/D18/12,0) -> 0 | L18: =(L17+J18)*(1+Inputs!B17) -> 43407.36 | M18: =L18/E18 -> 43407.36 | N18: =N17+K18*12/E18 -> 0
A19: 14 | B19: =B18+G18+H18+I18 -> 3.1000018e+13 | C19: =C18*(1+Inputs!B14)*(1+Inputs!B16) -> 4.0507998e+13 | D19: =D18*(1+Inputs!B15) -> 3.6673383e+08 | E19: =E18*(1+Inputs!B16) -> 1 | F19: =MAX(0,D19*Inputs!B15) -> 1833669.1 | G19: =Inputs!B9*(C19/D19)*F19 -> 5.0634998e+09 | H19: =Inputs!B10*C19*Inputs!B14 -> 6.8053437e+11 | I19: =Inputs!B11*B19 -> 0 | J19: =IF(D19>0,H19/D19,0) -> 1855.6629 | K19: =IF(D19>0,I19/D19/12,0) -> 0 | L19: =(L18+J19)*(1+Inputs!B17) -> 48205.12 | M19: =L19/E19 -> 48205.12 | N19: =N18+K19*12/E19 -> 0
A20: 15 | B20: =B19+G19+H19+I19 -> 3.1685616e+13 | C20: =C19*(1+Inputs!B14)*(1+Inputs!B16) -> 4.1318158e+13 | D20: =D19*(1+Inputs!B15) -> 3.685675e+08 | E20: =E19*(1+Inputs!B16) -> 1 | F20: =MAX(0,D20*Inputs!B15) -> 1842837.5 | G20: =Inputs!B9*(C20/D20)*F20 -> 5.1647697e+09 | H20: =Inputs!B10*C20*Inputs!B14 -> 6.9414505e+11 | I20: =Inputs!B11*B20 -> 0 | J20: =IF(D20>0,H20/D20,0) -> 1883.3594 | K20: =IF(D20>0,I20/D20/12,0) -> 0 | L20: =(L19+J20)*(1+Inputs!B17) -> 53344.23 | M20: =L20/E20 -> 53344.23 | N20: =N19+K20*12/E20 -> 0
A21: 16 | B21: =B20+G20+H20+I20 -> 32384926020041 | C21: =C20*(1+Inputs!B14)*(1+Inputs!B16) -> 4.2144521e+13 | D21: =D20*(1+Inputs!B15) -> 3.7041033e+08 | E21: =E20*(1+Inputs!B16) -> 1 | F21: =MAX(0,D21*Inputs!B15) -> 1852051.7 | G21: =Inputs!B9*(C21/D21)*F21 -> 5.2680651e+09 | H21: =Inputs!B10*C21*Inputs!B14 -> 7.0802796e+11 | I21: =Inputs!B11*B21 -> 0 | J21: =IF(D21>0,H21/D21,0) -> 1911.4692 | K21: =IF(D21>0,I21/D21/12,0) -> 0 | L21: =(L20+J21)*(1+Inputs!B17) -> 58847.32 | M21: =L21/E21 -> 58847.32 | N21: =N20+K21*12/E21 -> 0
A22: 17 | B22: =B21+G21+H21+I21 -> 3.3098222e+13 | C22: =C21*(1+Inputs!B14)*(1+Inputs!B16) -> 4.2987412e+13 | D22: =D21*(1+Inputs!B15) -> 3.7226239e+08 | E22: =E21*(1+Inputs!B16) -> 1 | F22: =MAX(0,D22*Inputs!B15) -> 1861311.9 | G22: =Inputs!B9*(C22/D22)*F22 -> 5.3734264e+09 | H22: =Inputs!B10*C22*Inputs!B14 -> 7.2218851e+11 | I22: =Inputs!B11*B22 -> 0 | J22: =IF(D22>0,H22/D22,0) -> 1939.9986 | K22: =IF(D22>0,I22/D22/12,0) -> 0 | L22: =(L21+J22)*(1+Inputs!B17) -> 64738.494 | M22: =L22/E22 -> 64738.494 | N22: =N21+K22*12/E22 -> 0
A23: 18 | B23: =B22+G22+H22+I22 -> 3.3825784e+13 | C23: =C22*(1+Inputs!B14)*(1+Inputs!B16) -> 4.384716e+13 | D23: =D22*(1+Inputs!B15) -> 3.741237e+08 | E23: =E22*(1+Inputs!B16) -> 1 | F23: =MAX(0,D23*Inputs!B15) -> 1870618.5 | G23: =Inputs!B9*(C23/D23)*F23 -> 5.480895e+09 | H23: =Inputs!B10*C23*Inputs!B14 -> 7.3663228e+11 | I23: =Inputs!B11*B23 -> 0 | J23: =IF(D23>0,H23/D23,0) -> 1968.9538 | K23: =IF(D23>0,I23/D23/12,0) -> 0 | L23: =(L22+J23)*(1+Inputs!B17) -> 71043.432 | M23: =L23/E23 -> 71043.432 | N23: =N22+K23*12/E23 -> 0
A24: 19 | B24: =B23+G23+H23+I23 -> 3.4567897e+13 | C24: =C23*(1+Inputs!B14)*(1+Inputs!B16) -> 4.4724103e+13 | D24: =D23*(1+Inputs!B15) -> 3.7599432e+08 | E24: =E23*(1+Inputs!B16) -> 1 | F24: =MAX(0,D24*Inputs!B15) -> 1879971.6 | G24: =Inputs!B9*(C24/D24)*F24 -> 5.5905129e+09 | H24: =Inputs!B10*C24*Inputs!B14 -> 7.5136493e+11 | I24: =Inputs!B11*B24 -> 0 | J24: =IF(D24>0,H24/D24,0) -> 1998.3412 | K24: =IF(D24>0,I24/D24/12,0) -> 0 | L24: =(L23+J24)*(1+Inputs!B17) -> 77789.489 | M24: =L24/E24 -> 77789.489 | N24: =N23+K24*12/E24 -> 0
A25: 20 | B25: =B24+G24+H24+I24 -> 3.5324853e+13 | C25: =C24*(1+Inputs!B14)*(1+Inputs!B16) -> 4.5618585e+13 | D25: =D24*(1+Inputs!B15) -> 3.7787429e+08 | E25: =E24*(1+Inputs!B16) -> 1 | F25: =MAX(0,D25*Inputs!B15) -> 1889371.4 | G25: =Inputs!B9*(C25/D25)*F25 -> 5.7023231e+09 | H25: =Inputs!B10*C25*Inputs!B14 -> 7.6639223e+11 | I25: =Inputs!B11*B25 -> 0 | J25: =IF(D25>0,H25/D25,0) -> 2028.1672 | K25: =IF(D25>0,I25/D25/12,0) -> 0 | L25: =(L24+J25)*(1+Inputs!B17) -> 85005.804 | M25: =L25/E25 -> 85005.804 | N25: =N24+K25*12/E25 -> 0
A26: 21 | B26: =B25+G25+H25+I25 -> 36096947156175 | C26: =C25*(1+Inputs!B14)*(1+Inputs!B16) -> 4.6530957e+13 | D26: =D25*(1+Inputs!B15) -> 3.7976366e+08 | E26: =E25*(1+Inputs!B16) -> 1 | F26: =MAX(0,D26*Inputs!B15) -> 1898818.3 | G26: =Inputs!B9*(C26/D26)*F26 -> 5.8163696e+09 | H26: =Inputs!B10*C26*Inputs!B14 -> 7.8172007e+11 | I26: =Inputs!B11*B26 -> 0 | J26: =IF(D26>0,H26/D26,0) -> 2058.4383 | K26: =IF(D26>0,I26/D26/12,0) -> 0 | L26: =(L25+J26)*(1+Inputs!B17) -> 92723.418 | M26: =L26/E26 -> 92723.418 | N26: =N25+K26*12/E26 -> 0
A27: 22 | B27: =B26+G26+H26+I26 -> 3.6884484e+13 | C27: =C26*(1+Inputs!B14)*(1+Inputs!B16) -> 4.7461576e+13 | D27: =D26*(1+Inputs!B15) -> 3.8166248e+08 | E27: =E26*(1+Inputs!B16) -> 1 | F27: =MAX(0,D27*Inputs!B15) -> 1908312.4 | G27: =Inputs!B9*(C27/D27)*F27 -> 5.932697e+09 | H27: =Inputs!B10*C27*Inputs!B14 -> 7.9735447e+11 | I27: =Inputs!B11*B27 -> 0 | J27: =IF(D27>0,H27/D27,0) -> 2089.1613 | K27: =IF(D27>0,I27/D27/12,0) -> 0 | L27: =(L26+J27)*(1+Inputs!B17) -> 100975.4 | M27: =L27/E27 -> 100975.4 | N27: =N26+K27*12/E27 -> 0
A28: 23 | B28: =B27+G27+H27+I27 -> 3.7687771e+13 | C28: =C27*(1+Inputs!B14)*(1+Inputs!B16) -> 4.8410807e+13 | D28: =D27*(1+Inputs!B15) -> 3.8357079e+08 | E28: =E27*(1+Inputs!B16) -> 1 | F28: =MAX(0,D28*Inputs!B15) -> 1917853.9 | G28: =Inputs!B9*(C28/D28)*F28 -> 6.0513509e+09 | H28: =Inputs!B10*C28*Inputs!B14 -> 8.1330156e+11 | I28: =Inputs!B11*B28 -> 0 | J28: =IF(D28>0,H28/D28,0) -> 2120.3428 | K28: =IF(D28>0,I28/D28/12,0) -> 0 | L28: =(L27+J28)*(1+Inputs!B17) -> 109796.96 | M28: =L28/E28 -> 109796.96 | N28: =N27+K28*12/E28 -> 0
A29: 24 | B29: =B28+G28+H28+I28 -> 3.8507124e+13 | C29: =C28*(1+Inputs!B14)*(1+Inputs!B16) -> 4.9379024e+13 | D29: =D28*(1+Inputs!B15) -> 3.8548864e+08 | E29: =E28*(1+Inputs!B16) -> 1 | F29: =MAX(0,D29*Inputs!B15) -> 1927443.2 | G29: =Inputs!B9*(C29/D29)*F29 -> 6.1723779e+09 | H29: =Inputs!B10*C29*Inputs!B14 -> 8.295676e+11 | I29: =Inputs!B11*B29 -> 0 | J29: =IF(D29>0,H29/D29,0) -> 2151.9897 | K29: =IF(D29>0,I29/D29/12,0) -> 0 | L29: =(L28+J29)*(1+Inputs!B17) -> 119225.63 | M29: =L29/E29 -> 119225.63 | N29: =N28+K29*12/E29 -> 0
A30: 25 | B30: =B29+G29+H29+I29 -> 3.9342864e+13 | C30: =C29*(1+Inputs!B14)*(1+Inputs!B16) -> 5.0366604e+13 | D30: =D29*(1+Inputs!B15) -> 3.8741609e+08 | E30: =E29*(1+Inputs!B16) -> 1 | F30: =MAX(0,D30*Inputs!B15) -> 1937080.4 | G30: =Inputs!B9*(C30/D30)*F30 -> 6.2958255e+09 | H30: =Inputs!B10*C30*Inputs!B14 -> 8.4615895e+11 | I30: =Inputs!B11*B30 -> 0 | J30: =IF(D30>0,H30/D30,0) -> 2184.109 | K30: =IF(D30>0,I30/D30/12,0) -> 0 | L30: =(L29+J30)*(1+Inputs!B17) -> 129301.38 | M30: =L30/E30 -> 129301.38 | N30: =N29+K30*12/E30 -> 0
A31: 26 | B31: =B30+G30+H30+I30 -> 4.0195318e+13 | C31: =C30*(1+Inputs!B14)*(1+Inputs!B16) -> 5.1373936e+13 | D31: =D30*(1+Inputs!B15) -> 3.8935317e+08 | E31: =E30*(1+Inputs!B16) -> 1 | F31: =MAX(0,D31*Inputs!B15) -> 1946765.8 | G31: =Inputs!B9*(C31/D31)*F31 -> 6.421742e+09 | H31: =Inputs!B10*C31*Inputs!B14 -> 8.6308213e+11 | I31: =Inputs!B11*B31 -> 0 | J31: =IF(D31>0,H31/D31,0) -> 2216.7076 | K31: =IF(D31>0,I31/D31/12,0) -> 0 | L31: =(L30+J31)*(1+Inputs!B17) -> 140066.76 | M31: =L31/E31 -> 140066.76 | N31: =N30+K31*12/E31 -> 0
A32: 27 | B32: =B31+G31+H31+I31 -> 4.1064822e+13 | C32: =C31*(1+Inputs!B14)*(1+Inputs!B16) -> 52401414832882 | D32: =D31*(1+Inputs!B15) -> 3.9129993e+08 | E32: =E31*(1+Inputs!B16) -> 1 | F32: =MAX(0,D32*Inputs!B15) -> 1956499.7 | G32: =Inputs!B9*(C32/D32)*F32 -> 6.5501769e+09 | H32: =Inputs!B10*C32*Inputs!B14 -> 8.8034377e+11 | I32: =Inputs!B11*B32 -> 0 | J32: =IF(D32>0,H32/D32,0) -> 2249.7928 | K32: =IF(D32>0,I32/D32/12,0) -> 0 | L32: =(L31+J32)*(1+Inputs!B17) -> 151567.13 | M32: =L32/E32 -> 151567.13 | N32: =N31+K32*12/E32 -> 0
A33: 28 | B33: =B32+G32+H32+I32 -> 4.1951716e+13 | C33: =C32*(1+Inputs!B14)*(1+Inputs!B16) -> 5.3449443e+13 | D33: =D32*(1+Inputs!B15) -> 3.9325643e+08 | E33: =E32*(1+Inputs!B16) -> 1 | F33: =MAX(0,D33*Inputs!B15) -> 1966282.2 | G33: =Inputs!B9*(C33/D33)*F33 -> 6.6811804e+09 | H33: =Inputs!B10*C33*Inputs!B14 -> 8.9795064e+11 | I33: =Inputs!B11*B33 -> 0 | J33: =IF(D33>0,H33/D33,0) -> 2283.3718 | K33: =IF(D33>0,I33/D33/12,0) -> 0 | L33: =(L32+J33)*(1+Inputs!B17) -> 163850.78 | M33: =L33/E33 -> 163850.78 | N33: =N32+K33*12/E33 -> 0
A34: 29 | B34: =B33+G33+H33+I33 -> 4.2856348e+13 | C34: =C33*(1+Inputs!B14)*(1+Inputs!B16) -> 5.4518432e+13 | D34: =D33*(1+Inputs!B15) -> 3.9522271e+08 | E34: =E33*(1+Inputs!B16) -> 1 | F34: =MAX(0,D34*Inputs!B15) -> 1976113.6 | G34: =Inputs!B9*(C34/D34)*F34 -> 6.814804e+09 | H34: =Inputs!B10*C34*Inputs!B14 -> 9.1590966e+11 | I34: =Inputs!B11*B34 -> 0 | J34: =IF(D34>0,H34/D34,0) -> 2317.452 | K34: =IF(D34>0,I34/D34/12,0) -> 0 | L34: =(L33+J34)*(1+Inputs!B17) -> 176969.17 | M34: =L34/E34 -> 176969.17 | N34: =N33+K34*12/E34 -> 0
A35: 30 | B35: =B34+G34+H34+I34 -> 4.3779073e+13 | C35: =C34*(1+Inputs!B14)*(1+Inputs!B16) -> 55608800631973 | D35: =D34*(1+Inputs!B15) -> 3.9719883e+08 | E35: =E34*(1+Inputs!B16) -> 1 | F35: =MAX(0,D35*Inputs!B15) -> 1985994.1 | G35: =Inputs!B9*(C35/D35)*F35 -> 6.9511001e+09 | H35: =Inputs!B10*C35*Inputs!B14 -> 9.3422785e+11 | I35: =Inputs!B11*B35 -> 0 | J35: =IF(D35>0,H35/D35,0) -> 2352.0408 | K35: =IF(D35>0,I35/D35/12,0) -> 0 | L35: =(L34+J35)*(1+Inputs!B17) -> 190977.09 | M35: =L35/E35 -> 190977.09 | N35: =N34+K35*12/E35 -> 0
A36: 31 | B36: =B35+G35+H35+I35 -> 4.4720251e+13 | C36: =C35*(1+Inputs!B14)*(1+Inputs!B16) -> 5.6720977e+13 | D36: =D35*(1+Inputs!B15) -> 3.9918482e+08 | E36: =E35*(1+Inputs!B16) -> 1 | F36: =MAX(0,D36*Inputs!B15) -> 1995924.1 | G36: =Inputs!B9*(C36/D36)*F36 -> 7.0901221e+09 | H36: =Inputs!B10*C36*Inputs!B14 -> 9.5291241e+11 | I36: =Inputs!B11*B36 -> 0 | J36: =IF(D36>0,H36/D36,0) -> 2387.1459 | K36: =IF(D36>0,I36/D36/12,0) -> 0 | L36: =(L35+J36)*(1+Inputs!B17) -> 205932.91 | M36: =L36/E36 -> 205932.91 | N36: =N35+K36*12/E36 -> 0
A37: 32 | B37: =B36+G36+H36+I36 -> 4.5680254e+13 | C37: =C36*(1+Inputs!B14)*(1+Inputs!B16) -> 5.7855396e+13 | D37: =D36*(1+Inputs!B15) -> 4.0118075e+08 | E37: =E36*(1+Inputs!B16) -> 1 | F37: =MAX(0,D37*Inputs!B15) -> 2005903.7 | G37: =Inputs!B9*(C37/D37)*F37 -> 7.2319245e+09 | H37: =Inputs!B10*C37*Inputs!B14 -> 9.7197066e+11 | I37: =Inputs!B11*B37 -> 0 | J37: =IF(D37>0,H37/D37,0) -> 2422.7749 | K37: =IF(D37>0,I37/D37/12,0) -> 0 | L37: =(L36+J37)*(1+Inputs!B17) -> 221898.8 | M37: =L37/E37 -> 221898.8 | N37: =N36+K37*12/E37 -> 0
A38: 33 | B38: =B37+G37+H37+I37 -> 4.6659457e+13 | C38: =C37*(1+Inputs!B14)*(1+Inputs!B16) -> 5.9012504e+13 | D38: =D37*(1+Inputs!B15) -> 4.0318665e+08 | E38: =E37*(1+Inputs!B16) -> 1 | F38: =MAX(0,D38*Inputs!B15) -> 2015933.3 | G38: =Inputs!B9*(C38/D38)*F38 -> 7.376563e+09 | H38: =Inputs!B10*C38*Inputs!B14 -> 9.9141007e+11 | I38: =Inputs!B11*B38 -> 0 | J38: =IF(D38>0,H38/D38,0) -> 2458.9358 | K38: =IF(D38>0,I38/D38/12,0) -> 0 | L38: =(L37+J38)*(1+Inputs!B17) -> 238940.99 | M38: =L38/E38 -> 238940.99 | N38: =N37+K38*12/E38 -> 0
A39: 34 | B39: =B38+G38+H38+I38 -> 47658243227428 | C39: =C38*(1+Inputs!B14)*(1+Inputs!B16) -> 6.0192754e+13 | D39: =D38*(1+Inputs!B15) -> 4.0520258e+08 | E39: =E38*(1+Inputs!B16) -> 1 | F39: =MAX(0,D39*Inputs!B15) -> 2026012.9 | G39: =Inputs!B9*(C39/D39)*F39 -> 7.5240943e+09 | H39: =Inputs!B10*C39*Inputs!B14 -> 1.0112383e+12 | I39: =Inputs!B11*B39 -> 0 | J39: =IF(D39>0,H39/D39,0) -> 2495.6363 | K39: =IF(D39>0,I39/D39/12,0) -> 0 | L39: =(L38+J39)*(1+Inputs!B17) -> 257130.01 | M39: =L39/E39 -> 257130.01 | N39: =N38+K39*12/E39 -> 0
A40: 35 | B40: =B39+G39+H39+I39 -> 4.8677006e+13 | C40: =C39*(1+Inputs!B14)*(1+Inputs!B16) -> 6.1396609e+13 | D40: =D39*(1+Inputs!B15) -> 4.072286e+08 | E40: =E39*(1+Inputs!B16) -> 1 | F40: =MAX(0,D40*Inputs!B15) -> 2036143 | G40: =Inputs!B9*(C40/D40)*F40 -> 7.6745762e+09 | H40: =Inputs!B10*C40*Inputs!B14 -> 1.031463e+12 | I40: =Inputs!B11*B40 -> 0 | J40: =IF(D40>0,H40/D40,0) -> 2532.8846 | K40: =IF(D40>0,I40/D40/12,0) -> 0 | L40: =(L39+J40)*(1+Inputs!B17) -> 276540.98 | M40: =L40/E40 -> 276540.98 | N40: =N39+K40*12/E40 -> 0
A41: 36 | B41: =B40+G40+H40+I40 -> 4.9716143e+13 | C41: =C40*(1+Inputs!B14)*(1+Inputs!B16) -> 6.2624541e+13 | D41: =D40*(1+Inputs!B15) -> 4.0926474e+08 | E41: =E40*(1+Inputs!B16) -> 1 | F41: =MAX(0,D41*Inputs!B15) -> 2046323.7 | G41: =Inputs!B9*(C41/D41)*F41 -> 7.8280677e+09 | H41: =Inputs!B10*C41*Inputs!B14 -> 1.0520923e+12 | I41: =Inputs!B11*B41 -> 0 | J41: =IF(D41>0,H41/D41,0) -> 2570.6888 | K41: =IF(D41>0,I41/D41/12,0) -> 0 | L41: =(L40+J41)*(1+Inputs!B17) -> 297253.93 | M41: =L41/E41 -> 297253.93 | N41: =N40+K41*12/E41 -> 0
...

Sheet Summary
A1: Headline outcomes at horizon
A2: Pulled live from Projection sheet using the Inputs!horizon value.
A4: Output | B4: Value | C4: Definition
A5: Stable Floor at horizon (real $) | B5: =INDEX(Projection!M5:M85,MATCH(Inputs!B23,Projection!A5:A85,0)) -> 2105506 | C5: Locked equity for one citizen, in launch-year purchasing power.
A6: Annual real income at horizon | B6: =INDEX(Projection!M5:M85,MATCH(Inputs!B23,Projection!A5:A85,0))*Inputs!B24 -> 84220.239 | C6: Stable Floor × withdrawal rate.
A7: K3 monthly dividend, year 1 | B7: =INDEX(Projection!K5:K85,2) -> 0 | C7: K3 spendable dividend per citizen, first year.
A8: K3 cumulative lifetime (real $) | B8: =INDEX(Projection!N5:N85,MATCH(Inputs!B23,Projection!A5:A85,0)) -> 0 | C8: Total dividend received by horizon, today dollars.
A9: Total real wealth at horizon | B9: =INDEX(Projection!M5:M85,MATCH(Inputs!B23,Projection!A5:A85,0))+INDEX(Projection!N5:N85,MATCH(Inputs!B23,Projection!A5:A85,0)) -> 2105506 | C9: Stable Floor + cumulative K3 (both real $).
A10: Total issuance / M2, year 1 | B10: =(INDEX(Projection!G5:G85,2)+INDEX(Projection!H5:H85,2)+INDEX(Projection!I5:I85,2))/INDEX(Projection!B5:B85,2) -> 0.022825092 | C10: Annual K1+K2+K3 as fraction of money supply.
A11: Total issuance / GDP, year 1 | B11: =(INDEX(Projection!G5:G85,2)+INDEX(Projection!H5:H85,2)+INDEX(Projection!I5:I85,2))/INDEX(Projection!C5:C85,2) -> 0.016925 | C11: Annual K1+K2+K3 as fraction of GDP.
A12: M2 at horizon ($) | B12: =INDEX(Projection!B5:B85,MATCH(Inputs!B23,Projection!A5:A85,0)) -> 9.0832823e+13 | C12: Final money supply.
A13: GDP at horizon ($) | B13: =INDEX(Projection!C5:C85,MATCH(Inputs!B23,Projection!A5:A85,0)) -> 111211459419972 | C13: Final nominal GDP.
A14: Population at horizon | B14: =INDEX(Projection!D5:D85,MATCH(Inputs!B23,Projection!A5:A85,0)) -> 4.7295533e+08 | C14: Final citizen count.
A15: CPI index at horizon | B15: =INDEX(Projection!E5:E85,MATCH(Inputs!B23,Projection!A5:A85,0)) -> 1 | C15: Price level relative to launch (1.0 = no change).

Sheet Comparison
A1: How does the Citizens Standard compare to real-world outcomes?
A2: Each column shows what one citizen actually receives under that system, using real-world median data — not theoretical maximums. Toggle the scenario in the yellow cell below to switch between median, average, and post-SS-cut outcomes.
A4: Real-world data anchors
A5: Median 401(k) at age 55-64 | B5: 87571 | C5: Vanguard 2025 — half of Americans have less
A6: Average 401(k) at age 55-64 | B6: 244750 | C6: Vanguard 2025 — skewed by top earners
A7: Average SS benefit (annual) | B7: 24953 | C7: SSA Mar 2026 — $2,079.49/mo × 12
A8: SS benefit cut after trust depletion | B8: 0.23 | C8: 2025 SSA Trustees Report — projected ~2034
A9: Alaska PFD (annual) | B9: 1700 | C9: Alaska DOR — recent average
A10: UBI proposal (monthly) | B10: 1000 | C10: Adjustable — common UBI proposal level
A11: MMT jobs guarantee wage | B11: 31200 | C11: $15/hr × 2080 hrs
A13: Scenario | B13: median | C13: Type: median, average, or ss-cut
A15: Lifetime delivery to one citizen, age 0 → horizon
A16: Metric | B16: Citizens Standard | C16: Fed status quo + SS | D16: Chicago Plan | E16: Friedman k-rule | F16: Bitcoin / fixed supply | G16: Alaska PFD (US-scale) | H16: UBI (tax-funded) | I16: MMT + jobs guarantee
A17: Wealth at horizon (real $) | B17: =Summary!B5 -> 2105506 | C17: =IF($B$13="average",$B$6,$B$5) -> 87571 | D17: =IF($B$13="average",$B$6,$B$5) -> 87571 | E17: =IF($B$13="average",$B$6,$B$5) -> 87571 | F17: =IF($B$13="average",$B$6,$B$5) -> 87571 | G17: =IF($B$13="average",$B$6,$B$5) -> 87571 | H17: =IF($B$13="average",$B$6,$B$5) -> 87571 | I17: =IF($B$13="average",$B$6,$B$5) -> 87571
A18: Lifetime cash transfers (real $) | B18: =Summary!B8 -> 0 | C18: 0 | D18: 0 | E18: 0 | F18: 0 | G18: =$B$9*Inputs!B23 -> 110500 | H18: =$B$10*12*Inputs!B23 -> 780000 | I18: =$B$11*43 -> 1341600
A19: Annual retirement income | B19: =Summary!B5*Inputs!B24+Projection!K5*12 -> 84220.239 | C19: =IF($B$13="average",$B$6,$B$5)*Inputs!B24+IF($B$13="ss-cut",$B$7*(1-$B$8),$B$7) -> 28455.84 | D19: =IF($B$13="average",$B$6,$B$5)*Inputs!B24 -> 3502.84 | E19: =IF($B$13="average",$B$6,$B$5)*Inputs!B24 -> 3502.84 | F19: =IF($B$13="average",$B$6,$B$5)*Inputs!B24 -> 3502.84 | G19: =IF($B$13="average",$B$6,$B$5)*Inputs!B24+$B$9 -> 5202.84 | H19: =IF($B$13="average",$B$6,$B$5)*Inputs!B24+$B$10*12 -> 15502.84 | I19: =IF($B$13="average",$B$6,$B$5)*Inputs!B24 -> 3502.84
A21: Structural properties
A22: Rules-based (no committee discretion) | B22: ✓ | C22: ✗ | D22: ✓ | E22: ✓ | F22: ✓ | G22: partial | H22: ✗ | I22: ✗
A23: Per-citizen distribution | B23: ✓ | C23: ✗ | D23: ✗ | E23: ✗ | F23: ✗ | G23: ✓ | H23: ✓ | I23: partial
A24: Real-growth response | B24: ✓ | C24: partial | D24: ✗ | E24: ✗ | F24: ✗ | G24: partial | H24: ✗ | I24: ✓
A25: Crisis response capacity | B25: bounded | C25: unbounded | D25: limited | E25: none | F25: none | G25: limited | H25: limited | I25: unbounded
A26: Constitutional / hard to revoke | B26: ✓ | C26: ✗ | D26: ✗ | E26: ✗ | F26: ✓ | G26: ✗ | H26: ✗ | I26: ✗
A27: Funded by | B27: Seigniorage | C27: Mixed | D27: Govt seigniorage | E27: Fed seigniorage | F27: Mining rewards | G27: Resource royalty | H27: Taxation | I27: Treasury seigniorage
A29: Honest caveats
A30: Citizens Standard | B30: Single-cohort projection with constant rates. K3 modeled as flat % of M2 (not full price-level path targeting). Real values use your CPI input.
A31: Fed status quo | B31: Uses real-world median 401(k) balance ($87,571 at 55-64, Vanguard 2025) — what Americans actually retire with, not what disciplined savers theoretically could. Add SS at scenario-appropriate level.
A32: Chicago Plan | B32: 1933 proposal eliminated bank money creation but never specified seigniorage distribution. Citizens still rely on personal savings.
A33: Friedman k-rule | B33: Specified rate of monetary expansion but never the distribution channel. Nothing reaches citizens directly.
A34: Bitcoin | B34: Treated as savings vehicle with same equity-equivalent return for fair comparison. Real Bitcoin returns have been wildly volatile.
A35: Alaska PFD | B35: Modeled at $1,700/yr default. Real Alaska PFD funded by oil royalties, not seigniorage.
A36: UBI | B36: Funded by taxation, not money creation. Fiscal sustainability question is real and unresolved at scale.
A37: MMT | B37: Assumes citizen employed in jobs guarantee for full 43-year working life. Inflation control depends on tax policy responding correctly to demand pressure.
A39: Data sources
A40: Vanguard, How America Saves 2025: median 401(k) at 55-64 = $87,571; average = $244,750.
A41: Social Security Administration, Monthly Statistical Snapshot, March 2026: average retired-worker benefit = $2,079.49/month.
A42: 2025 SSA Trustees Report: OASI trust fund projected to deplete ~2034; benefits cut to ~77-81% of scheduled.
A43: SSA/CBO replacement rate analyses: ~37-42% for average earner.
A44: Alaska Department of Revenue: PFD historical range $1,200-$3,300/year.

Sheet Stress Test
A1: Stress Test — Historical Adverse Sequences
A2: What happens to the Stable Floor when a citizen lives through a real historical bad period? Each scenario applies year-by-year actual returns and inflation from a real era. The framework's structural advantage is what survives this stress test.
A4: Year-by-year simulation
A5: Year | B5: Age | C5: Smooth baseline | G5: Great Depression (1929-1944) | K5: 1970s Stagflation (1966-1982) | O5: 2000s Lost Decade (2000-2009)
C6: Return | D6: CPI | E6: Floor (nom) | F6: Floor (real) | G6: Return | H6: CPI | I6: Floor (nom) | J6: Floor (real) | K6: Return | L6: CPI | M6: Floor (nom) | N6: Floor (real) | O6: Return | P6: CPI | Q6: Floor (nom) | R6: Floor (real)
A7: 0 | B7: 0 | C7: =Inputs!B17 -> 0.065 | D7: =Inputs!B16 -> 0 | E7: =((Projection!G5/MAX(Projection!F5,1))+Projection!J5)*(1+C7) -> 3996.1167 | F7: =E7/(1+Inputs!B16)^(0+1) -> 3996.1167 | G7: =Inputs!B17 -> 0.065 | H7: =Inputs!B16 -> 0 | I7: =((Projection!G5/MAX(Projection!F5,1))+Projection!J5)*(1+G7) -> 3996.1167 | J7: =I7/(1+H7) -> 3996.1167 | K7: =Inputs!B17 -> 0.065 | L7: =Inputs!B16 -> 0 | M7: =((Projection!G5/MAX(Projection!F5,1))+Projection!J5)*(1+K7) -> 3996.1167 | N7: =M7/(1+L7) -> 3996.1167 | O7: =Inputs!B17 -> 0.065 | P7: =Inputs!B16 -> 0 | Q7: =((Projection!G5/MAX(Projection!F5,1))+Projection!J5)*(1+O7) -> 3996.1167 | R7: =Q7/(1+P7) -> 3996.1167
A8: 1 | B8: 1 | C8: =Inputs!B17 -> 0.065 | D8: =Inputs!B16 -> 0 | E8: =(E7+Projection!J6)*(1+C8) -> 5885.9306 | F8: =E8/(1+Inputs!B16)^(1+1) -> 5885.9306 | G8: =Inputs!B17 -> 0.065 | H8: =Inputs!B16 -> 0 | I8: =(I7+Projection!J6)*(1+G8) -> 5885.9306 | J8: =I8/PRODUCT(1+H$7:H8) -> 5885.9306 | K8: =Inputs!B17 -> 0.065 | L8: =Inputs!B16 -> 0 | M8: =(M7+Projection!J6)*(1+K8) -> 5885.9306 | N8: =M8/PRODUCT(1+L$7:L8) -> 5885.9306 | O8: =Inputs!B17 -> 0.065 | P8: =Inputs!B16 -> 0 | Q8: =(Q7+Projection!J6)*(1+O8) -> 5885.9306 | R8: =Q8/PRODUCT(1+P$7:P8) -> 5885.9306
A9: 2 | B9: 2 | C9: =Inputs!B17 -> 0.065 | D9: =Inputs!B16 -> 0 | E9: =(E8+Projection!J7)*(1+C9) -> 7922.9117 | F9: =E9/(1+Inputs!B16)^(2+1) -> 7922.9117 | G9: =Inputs!B17 -> 0.065 | H9: =Inputs!B16 -> 0 | I9: =(I8+Projection!J7)*(1+G9) -> 7922.9117 | J9: =I9/PRODUCT(1+H$7:H9) -> 7922.9117 | K9: =Inputs!B17 -> 0.065 | L9: =Inputs!B16 -> 0 | M9: =(M8+Projection!J7)*(1+K9) -> 7922.9117 | N9: =M9/PRODUCT(1+L$7:L9) -> 7922.9117 | O9: =Inputs!B17 -> 0.065 | P9: =Inputs!B16 -> 0 | Q9: =(Q8+Projection!J7)*(1+O9) -> 7922.9117 | R9: =Q9/PRODUCT(1+P$7:P9) -> 7922.9117
A10: 3 | B10: 3 | C10: =Inputs!B17 -> 0.065 | D10: =Inputs!B16 -> 0 | E10: =(E9+Projection!J8)*(1+C10) -> 10116.989 | F10: =E10/(1+Inputs!B16)^(3+1) -> 10116.989 | G10: =Inputs!B17 -> 0.065 | H10: =Inputs!B16 -> 0 | I10: =(I9+Projection!J8)*(1+G10) -> 10116.989 | J10: =I10/PRODUCT(1+H$7:H10) -> 10116.989 | K10: =Inputs!B17 -> 0.065 | L10: =Inputs!B16 -> 0 | M10: =(M9+Projection!J8)*(1+K10) -> 10116.989 | N10: =M10/PRODUCT(1+L$7:L10) -> 10116.989 | O10: =Inputs!B17 -> 0.065 | P10: =Inputs!B16 -> 0 | Q10: =(Q9+Projection!J8)*(1+O10) -> 10116.989 | R10: =Q10/PRODUCT(1+P$7:P10) -> 10116.989
A11: 4 | B11: 4 | C11: =Inputs!B17 -> 0.065 | D11: =Inputs!B16 -> 0 | E11: =(E10+Projection!J9)*(1+C11) -> 12478.742 | F11: =E11/(1+Inputs!B16)^(4+1) -> 12478.742 | G11: =Inputs!B17 -> 0.065 | H11: =Inputs!B16 -> 0 | I11: =(I10+Projection!J9)*(1+G11) -> 12478.742 | J11: =I11/PRODUCT(1+H$7:H11) -> 12478.742 | K11: =Inputs!B17 -> 0.065 | L11: =Inputs!B16 -> 0 | M11: =(M10+Projection!J9)*(1+K11) -> 12478.742 | N11: =M11/PRODUCT(1+L$7:L11) -> 12478.742 | O11: =Inputs!B17 -> 0.065 | P11: =Inputs!B16 -> 0 | Q11: =(Q10+Projection!J9)*(1+O11) -> 12478.742 | R11: =Q11/PRODUCT(1+P$7:P11) -> 12478.742
A12: 5 | B12: 5 | C12: =Inputs!B17 -> 0.065 | D12: =Inputs!B16 -> 0 | E12: =(E11+Projection!J10)*(1+C12) -> 15019.445 | F12: =E12/(1+Inputs!B16)^(5+1) -> 15019.445 | G12: =Inputs!B17 -> 0.065 | H12: =Inputs!B16 -> 0 | I12: =(I11+Projection!J10)*(1+G12) -> 15019.445 | J12: =I12/PRODUCT(1+H$7:H12) -> 15019.445 | K12: =Inputs!B17 -> 0.065 | L12: =Inputs!B16 -> 0 | M12: =(M11+Projection!J10)*(1+K12) -> 15019.445 | N12: =M12/PRODUCT(1+L$7:L12) -> 15019.445 | O12: =Inputs!B17 -> 0.065 | P12: =Inputs!B16 -> 0 | Q12: =(Q11+Projection!J10)*(1+O12) -> 15019.445 | R12: =Q12/PRODUCT(1+P$7:P12) -> 15019.445
A13: 6 | B13: 6 | C13: =Inputs!B17 -> 0.065 | D13: =Inputs!B16 -> 0 | E13: =(E12+Projection!J11)*(1+C13) -> 17751.108 | F13: =E13/(1+Inputs!B16)^(6+1) -> 17751.108 | G13: =Inputs!B17 -> 0.065 | H13: =Inputs!B16 -> 0 | I13: =(I12+Projection!J11)*(1+G13) -> 17751.108 | J13: =I13/PRODUCT(1+H$7:H13) -> 17751.108 | K13: =Inputs!B17 -> 0.065 | L13: =Inputs!B16 -> 0 | M13: =(M12+Projection!J11)*(1+K13) -> 17751.108 | N13: =M13/PRODUCT(1+L$7:L13) -> 17751.108 | O13: =Inputs!B17 -> 0.065 | P13: =Inputs!B16 -> 0 | Q13: =(Q12+Projection!J11)*(1+O13) -> 17751.108 | R13: =Q13/PRODUCT(1+P$7:P13) -> 17751.108
A14: 7 | B14: 7 | C14: =Inputs!B17 -> 0.065 | D14: =Inputs!B16 -> 0 | E14: =(E13+Projection!J12)*(1+C14) -> 20686.529 | F14: =E14/(1+Inputs!B16)^(7+1) -> 20686.529 | G14: =Inputs!B17 -> 0.065 | H14: =Inputs!B16 -> 0 | I14: =(I13+Projection!J12)*(1+G14) -> 20686.529 | J14: =I14/PRODUCT(1+H$7:H14) -> 20686.529 | K14: =Inputs!B17 -> 0.065 | L14: =Inputs!B16 -> 0 | M14: =(M13+Projection!J12)*(1+K14) -> 20686.529 | N14: =M14/PRODUCT(1+L$7:L14) -> 20686.529 | O14: =Inputs!B17 -> 0.065 | P14: =Inputs!B16 -> 0 | Q14: =(Q13+Projection!J12)*(1+O14) -> 20686.529 | R14: =Q14/PRODUCT(1+P$7:P14) -> 20686.529
A15: 8 | B15: 8 | C15: =Inputs!B17 -> 0.065 | D15: =Inputs!B16 -> 0 | E15: =(E14+Projection!J13)*(1+C15) -> 23839.343 | F15: =E15/(1+Inputs!B16)^(8+1) -> 23839.343 | G15: =Inputs!B17 -> 0.065 | H15: =Inputs!B16 -> 0 | I15: =(I14+Projection!J13)*(1+G15) -> 23839.343 | J15: =I15/PRODUCT(1+H$7:H15) -> 23839.343 | K15: =Inputs!B17 -> 0.065 | L15: =Inputs!B16 -> 0 | M15: =(M14+Projection!J13)*(1+K15) -> 23839.343 | N15: =M15/PRODUCT(1+L$7:L15) -> 23839.343 | O15: =Inputs!B17 -> 0.065 | P15: =Inputs!B16 -> 0 | Q15: =(Q14+Projection!J13)*(1+O15) -> 23839.343 | R15: =Q15/PRODUCT(1+P$7:P15) -> 23839.343
A16: 9 | B16: 9 | C16: =Inputs!B17 -> 0.065 | D16: =Inputs!B16 -> 0 | E16: =(E15+Projection!J14)*(1+C16) -> 27224.078 | F16: =E16/(1+Inputs!B16)^(9+1) -> 27224.078 | G16: =Inputs!B17 -> 0.065 | H16: =Inputs!B16 -> 0 | I16: =(I15+Projection!J14)*(1+G16) -> 27224.078 | J16: =I16/PRODUCT(1+H$7:H16) -> 27224.078 | K16: =Inputs!B17 -> 0.065 | L16: =Inputs!B16 -> 0 | M16: =(M15+Projection!J14)*(1+K16) -> 27224.078 | N16: =M16/PRODUCT(1+L$7:L16) -> 27224.078 | O16: =Inputs!B17 -> 0.065 | P16: =Inputs!B16 -> 0 | Q16: =(Q15+Projection!J14)*(1+O16) -> 27224.078 | R16: =Q16/PRODUCT(1+P$7:P16) -> 27224.078
A17: 10 | B17: 10 | C17: =Inputs!B17 -> 0.065 | D17: =Inputs!B16 -> 0 | E17: =(E16+Projection!J15)*(1+C17) -> 30856.212 | F17: =E17/(1+Inputs!B16)^(10+1) -> 30856.212 | G17: =Inputs!B17 -> 0.065 | H17: =Inputs!B16 -> 0 | I17: =(I16+Projection!J15)*(1+G17) -> 30856.212 | J17: =I17/PRODUCT(1+H$7:H17) -> 30856.212 | K17: =Inputs!B17 -> 0.065 | L17: =Inputs!B16 -> 0 | M17: =(M16+Projection!J15)*(1+K17) -> 30856.212 | N17: =M17/PRODUCT(1+L$7:L17) -> 30856.212 | O17: =Inputs!B17 -> 0.065 | P17: =Inputs!B16 -> 0 | Q17: =(Q16+Projection!J15)*(1+O17) -> 30856.212 | R17: =Q17/PRODUCT(1+P$7:P17) -> 30856.212
A18: 11 | B18: 11 | C18: =Inputs!B17 -> 0.065 | D18: =Inputs!B16 -> 0 | E18: =(E17+Projection!J16)*(1+C18) -> 34752.233 | F18: =E18/(1+Inputs!B16)^(11+1) -> 34752.233 | G18: =Inputs!B17 -> 0.065 | H18: =Inputs!B16 -> 0 | I18: =(I17+Projection!J16)*(1+G18) -> 34752.233 | J18: =I18/PRODUCT(1+H$7:H18) -> 34752.233 | K18: =Inputs!B17 -> 0.065 | L18: =Inputs!B16 -> 0 | M18: =(M17+Projection!J16)*(1+K18) -> 34752.233 | N18: =M18/PRODUCT(1+L$7:L18) -> 34752.233 | O18: =Inputs!B17 -> 0.065 | P18: =Inputs!B16 -> 0 | Q18: =(Q17+Projection!J16)*(1+O18) -> 34752.233 | R18: =Q18/PRODUCT(1+P$7:P18) -> 34752.233
A19: 12 | B19: 12 | C19: =Inputs!B17 -> 0.065 | D19: =Inputs!B16 -> 0 | E19: =(E18+Projection!J17)*(1+C19) -> 38929.711 | F19: =E19/(1+Inputs!B16)^(12+1) -> 38929.711 | G19: =Inputs!B17 -> 0.065 | H19: =Inputs!B16 -> 0 | I19: =(I18+Projection!J17)*(1+G19) -> 38929.711 | J19: =I19/PRODUCT(1+H$7:H19) -> 38929.711 | K19: =Inputs!B17 -> 0.065 | L19: =Inputs!B16 -> 0 | M19: =(M18+Projection!J17)*(1+K19) -> 38929.711 | N19: =M19/PRODUCT(1+L$7:L19) -> 38929.711 | O19: =Inputs!B17 -> 0.065 | P19: =Inputs!B16 -> 0 | Q19: =(Q18+Projection!J17)*(1+O19) -> 38929.711 | R19: =Q19/PRODUCT(1+P$7:P19) -> 38929.711
A20: 13 | B20: 13 | C20: =Inputs!B17 -> 0.065 | D20: =Inputs!B16 -> 0 | E20: =(E19+Projection!J18)*(1+C20) -> 43407.36 | F20: =E20/(1+Inputs!B16)^(13+1) -> 43407.36 | G20: =Inputs!B17 -> 0.065 | H20: =Inputs!B16 -> 0 | I20: =(I19+Projection!J18)*(1+G20) -> 43407.36 | J20: =I20/PRODUCT(1+H$7:H20) -> 43407.36 | K20: =Inputs!B17 -> 0.065 | L20: =Inputs!B16 -> 0 | M20: =(M19+Projection!J18)*(1+K20) -> 43407.36 | N20: =M20/PRODUCT(1+L$7:L20) -> 43407.36 | O20: =Inputs!B17 -> 0.065 | P20: =Inputs!B16 -> 0 | Q20: =(Q19+Projection!J18)*(1+O20) -> 43407.36 | R20: =Q20/PRODUCT(1+P$7:P20) -> 43407.36
A21: 14 | B21: 14 | C21: =Inputs!B17 -> 0.065 | D21: =Inputs!B16 -> 0 | E21: =(E20+Projection!J19)*(1+C21) -> 48205.12 | F21: =E21/(1+Inputs!B16)^(14+1) -> 48205.12 | G21: =Inputs!B17 -> 0.065 | H21: =Inputs!B16 -> 0 | I21: =(I20+Projection!J19)*(1+G21) -> 48205.12 | J21: =I21/PRODUCT(1+H$7:H21) -> 48205.12 | K21: =Inputs!B17 -> 0.065 | L21: =Inputs!B16 -> 0 | M21: =(M20+Projection!J19)*(1+K21) -> 48205.12 | N21: =M21/PRODUCT(1+L$7:L21) -> 48205.12 | O21: =Inputs!B17 -> 0.065 | P21: =Inputs!B16 -> 0 | Q21: =(Q20+Projection!J19)*(1+O21) -> 48205.12 | R21: =Q21/PRODUCT(1+P$7:P21) -> 48205.12
A22: 15 | B22: 15 | C22: =Inputs!B17 -> 0.065 | D22: =Inputs!B16 -> 0 | E22: =(E21+Projection!J20)*(1+C22) -> 53344.23 | F22: =E22/(1+Inputs!B16)^(15+1) -> 53344.23 | G22: =Inputs!B17 -> 0.065 | H22: =Inputs!B16 -> 0 | I22: =(I21+Projection!J20)*(1+G22) -> 53344.23 | J22: =I22/PRODUCT(1+H$7:H22) -> 53344.23 | K22: =Inputs!B17 -> 0.065 | L22: =Inputs!B16 -> 0 | M22: =(M21+Projection!J20)*(1+K22) -> 53344.23 | N22: =M22/PRODUCT(1+L$7:L22) -> 53344.23 | O22: =Inputs!B17 -> 0.065 | P22: =Inputs!B16 -> 0 | Q22: =(Q21+Projection!J20)*(1+O22) -> 53344.23 | R22: =Q22/PRODUCT(1+P$7:P22) -> 53344.23
A23: 16 | B23: 16 | C23: =Inputs!B17 -> 0.065 | D23: =Inputs!B16 -> 0 | E23: =(E22+Projection!J21)*(1+C23) -> 58847.32 | F23: =E23/(1+Inputs!B16)^(16+1) -> 58847.32 | G23: =Inputs!B17 -> 0.065 | H23: =Inputs!B16 -> 0 | I23: =(I22+Projection!J21)*(1+G23) -> 58847.32 | J23: =I23/PRODUCT(1+H$7:H23) -> 58847.32 | K23: =Inputs!B17 -> 0.065 | L23: =Inputs!B16 -> 0 | M23: =(M22+Projection!J21)*(1+K23) -> 58847.32 | N23: =M23/PRODUCT(1+L$7:L23) -> 58847.32 | O23: =Inputs!B17 -> 0.065 | P23: =Inputs!B16 -> 0 | Q23: =(Q22+Projection!J21)*(1+O23) -> 58847.32 | R23: =Q23/PRODUCT(1+P$7:P23) -> 58847.32
A24: 17 | B24: 17 | C24: =Inputs!B17 -> 0.065 | D24: =Inputs!B16 -> 0 | E24: =(E23+Projection!J22)*(1+C24) -> 64738.494 | F24: =E24/(1+Inputs!B16)^(17+1) -> 64738.494 | G24: =Inputs!B17 -> 0.065 | H24: =Inputs!B16 -> 0 | I24: =(I23+Projection!J22)*(1+G24) -> 64738.494 | J24: =I24/PRODUCT(1+H$7:H24) -> 64738.494 | K24: =Inputs!B17 -> 0.065 | L24: =Inputs!B16 -> 0 | M24: =(M23+Projection!J22)*(1+K24) -> 64738.494 | N24: =M24/PRODUCT(1+L$7:L24) -> 64738.494 | O24: =Inputs!B17 -> 0.065 | P24: =Inputs!B16 -> 0 | Q24: =(Q23+Projection!J22)*(1+O24) -> 64738.494 | R24: =Q24/PRODUCT(1+P$7:P24) -> 64738.494
A25: 18 | B25: 18 | C25: =Inputs!B17 -> 0.065 | D25: =Inputs!B16 -> 0 | E25: =(E24+Projection!J23)*(1+C25) -> 71043.432 | F25: =E25/(1+Inputs!B16)^(18+1) -> 71043.432 | G25: =Inputs!B17 -> 0.065 | H25: =Inputs!B16 -> 0 | I25: =(I24+Projection!J23)*(1+G25) -> 71043.432 | J25: =I25/PRODUCT(1+H$7:H25) -> 71043.432 | K25: =Inputs!B17 -> 0.065 | L25: =Inputs!B16 -> 0 | M25: =(M24+Projection!J23)*(1+K25) -> 71043.432 | N25: =M25/PRODUCT(1+L$7:L25) -> 71043.432 | O25: =Inputs!B17 -> 0.065 | P25: =Inputs!B16 -> 0 | Q25: =(Q24+Projection!J23)*(1+O25) -> 71043.432 | R25: =Q25/PRODUCT(1+P$7:P25) -> 71043.432
A26: 19 | B26: 19 | C26: =Inputs!B17 -> 0.065 | D26: =Inputs!B16 -> 0 | E26: =(E25+Projection!J24)*(1+C26) -> 77789.489 | F26: =E26/(1+Inputs!B16)^(19+1) -> 77789.489 | G26: =Inputs!B17 -> 0.065 | H26: =Inputs!B16 -> 0 | I26: =(I25+Projection!J24)*(1+G26) -> 77789.489 | J26: =I26/PRODUCT(1+H$7:H26) -> 77789.489 | K26: =Inputs!B17 -> 0.065 | L26: =Inputs!B16 -> 0 | M26: =(M25+Projection!J24)*(1+K26) -> 77789.489 | N26: =M26/PRODUCT(1+L$7:L26) -> 77789.489 | O26: =Inputs!B17 -> 0.065 | P26: =Inputs!B16 -> 0 | Q26: =(Q25+Projection!J24)*(1+O26) -> 77789.489 | R26: =Q26/PRODUCT(1+P$7:P26) -> 77789.489
A27: 20 | B27: 20 | C27: =Inputs!B17 -> 0.065 | D27: =Inputs!B16 -> 0 | E27: =(E26+Projection!J25)*(1+C27) -> 85005.804 | F27: =E27/(1+Inputs!B16)^(20+1) -> 85005.804 | G27: =Inputs!B17 -> 0.065 | H27: =Inputs!B16 -> 0 | I27: =(I26+Projection!J25)*(1+G27) -> 85005.804 | J27: =I27/PRODUCT(1+H$7:H27) -> 85005.804 | K27: =Inputs!B17 -> 0.065 | L27: =Inputs!B16 -> 0 | M27: =(M26+Projection!J25)*(1+K27) -> 85005.804 | N27: =M27/PRODUCT(1+L$7:L27) -> 85005.804 | O27: =Inputs!B17 -> 0.065 | P27: =Inputs!B16 -> 0 | Q27: =(Q26+Projection!J25)*(1+O27) -> 85005.804 | R27: =Q27/PRODUCT(1+P$7:P27) -> 85005.804
A28: 21 | B28: 21 | C28: =Inputs!B17 -> 0.065 | D28: =Inputs!B16 -> 0 | E28: =(E27+Projection!J26)*(1+C28) -> 92723.418 | F28: =E28/(1+Inputs!B16)^(21+1) -> 92723.418 | G28: =Inputs!B17 -> 0.065 | H28: =Inputs!B16 -> 0 | I28: =(I27+Projection!J26)*(1+G28) -> 92723.418 | J28: =I28/PRODUCT(1+H$7:H28) -> 92723.418 | K28: =Inputs!B17 -> 0.065 | L28: =Inputs!B16 -> 0 | M28: =(M27+Projection!J26)*(1+K28) -> 92723.418 | N28: =M28/PRODUCT(1+L$7:L28) -> 92723.418 | O28: =Inputs!B17 -> 0.065 | P28: =Inputs!B16 -> 0 | Q28: =(Q27+Projection!J26)*(1+O28) -> 92723.418 | R28: =Q28/PRODUCT(1+P$7:P28) -> 92723.418
A29: 22 | B29: 22 | C29: =Inputs!B17 -> 0.065 | D29: =Inputs!B16 -> 0 | E29: =(E28+Projection!J27)*(1+C29) -> 100975.4 | F29: =E29/(1+Inputs!B16)^(22+1) -> 100975.4 | G29: =Inputs!B17 -> 0.065 | H29: =Inputs!B16 -> 0 | I29: =(I28+Projection!J27)*(1+G29) -> 100975.4 | J29: =I29/PRODUCT(1+H$7:H29) -> 100975.4 | K29: =Inputs!B17 -> 0.065 | L29: =Inputs!B16 -> 0 | M29: =(M28+Projection!J27)*(1+K29) -> 100975.4 | N29: =M29/PRODUCT(1+L$7:L29) -> 100975.4 | O29: =Inputs!B17 -> 0.065 | P29: =Inputs!B16 -> 0 | Q29: =(Q28+Projection!J27)*(1+O29) -> 100975.4 | R29: =Q29/PRODUCT(1+P$7:P29) -> 100975.4
A30: 23 | B30: 23 | C30: =Inputs!B17 -> 0.065 | D30: =Inputs!B16 -> 0 | E30: =(E29+Projection!J28)*(1+C30) -> 109796.96 | F30: =E30/(1+Inputs!B16)^(23+1) -> 109796.96 | G30: =Inputs!B17 -> 0.065 | H30: =Inputs!B16 -> 0 | I30: =(I29+Projection!J28)*(1+G30) -> 109796.96 | J30: =I30/PRODUCT(1+H$7:H30) -> 109796.96 | K30: =Inputs!B17 -> 0.065 | L30: =Inputs!B16 -> 0 | M30: =(M29+Projection!J28)*(1+K30) -> 109796.96 | N30: =M30/PRODUCT(1+L$7:L30) -> 109796.96 | O30: =Inputs!B17 -> 0.065 | P30: =Inputs!B16 -> 0 | Q30: =(Q29+Projection!J28)*(1+O30) -> 109796.96 | R30: =Q30/PRODUCT(1+P$7:P30) -> 109796.96
A31: 24 | B31: 24 | C31: =Inputs!B17 -> 0.065 | D31: =Inputs!B16 -> 0 | E31: =(E30+Projection!J29)*(1+C31) -> 119225.63 | F31: =E31/(1+Inputs!B16)^(24+1) -> 119225.63 | G31: =Inputs!B17 -> 0.065 | H31: =Inputs!B16 -> 0 | I31: =(I30+Projection!J29)*(1+G31) -> 119225.63 | J31: =I31/PRODUCT(1+H$7:H31) -> 119225.63 | K31: =Inputs!B17 -> 0.065 | L31: =Inputs!B16 -> 0 | M31: =(M30+Projection!J29)*(1+K31) -> 119225.63 | N31: =M31/PRODUCT(1+L$7:L31) -> 119225.63 | O31: =Inputs!B17 -> 0.065 | P31: =Inputs!B16 -> 0 | Q31: =(Q30+Projection!J29)*(1+O31) -> 119225.63 | R31: =Q31/PRODUCT(1+P$7:P31) -> 119225.63
A32: 25 | B32: 25 | C32: =Inputs!B17 -> 0.065 | D32: =Inputs!B16 -> 0 | E32: =(E31+Projection!J30)*(1+C32) -> 129301.38 | F32: =E32/(1+Inputs!B16)^(25+1) -> 129301.38 | G32: -0.13 | H32: 0 | I32: =(I31+Projection!J30)*(1+G32) -> 105626.48 | J32: =I32/PRODUCT(1+H$7:H32) -> 105626.48 | K32: =Inputs!B17 -> 0.065 | L32: =Inputs!B16 -> 0 | M32: =(M31+Projection!J30)*(1+K32) -> 129301.38 | N32: =M32/PRODUCT(1+L$7:L32) -> 129301.38 | O32: =Inputs!B17 -> 0.065 | P32: =Inputs!B16 -> 0 | Q32: =(Q31+Projection!J30)*(1+O32) -> 129301.38 | R32: =Q32/PRODUCT(1+P$7:P32) -> 129301.38
A33: 26 | B33: 26 | C33: =Inputs!B17 -> 0.065 | D33: =Inputs!B16 -> 0 | E33: =(E32+Projection!J31)*(1+C33) -> 140066.76 | F33: =E33/(1+Inputs!B16)^(26+1) -> 140066.76 | G33: -0.3 | H33: -0.024 | I33: =(I32+Projection!J31)*(1+G33) -> 75490.229 | J33: =I33/PRODUCT(1+H$7:H33) -> 77346.546 | K33: =Inputs!B17 -> 0.065 | L33: =Inputs!B16 -> 0 | M33: =(M32+Projection!J31)*(1+K33) -> 140066.76 | N33: =M33/PRODUCT(1+L$7:L33) -> 140066.76 | O33: =Inputs!B17 -> 0.065 | P33: =Inputs!B16 -> 0 | Q33: =(Q32+Projection!J31)*(1+O33) -> 140066.76 | R33: =Q33/PRODUCT(1+P$7:P33) -> 140066.76
A34: 27 | B34: 27 | C34: =Inputs!B17 -> 0.065 | D34: =Inputs!B16 -> 0 | E34: =(E33+Projection!J32)*(1+C34) -> 151567.13 | F34: =E34/(1+Inputs!B16)^(27+1) -> 151567.13 | G34: -0.45 | H34: -0.09 | I34: =(I33+Projection!J32)*(1+G34) -> 42757.012 | J34: =I34/PRODUCT(1+H$7:H34) -> 46985.727 | K34: =Inputs!B17 -> 0.065 | L34: =Inputs!B16 -> 0 | M34: =(M33+Projection!J32)*(1+K34) -> 151567.13 | N34: =M34/PRODUCT(1+L$7:L34) -> 151567.13 | O34: =Inputs!B17 -> 0.065 | P34: =Inputs!B16 -> 0 | Q34: =(Q33+Projection!J32)*(1+O34) -> 151567.13 | R34: =Q34/PRODUCT(1+P$7:P34) -> 151567.13
A35: 28 | B35: 28 | C35: =Inputs!B17 -> 0.065 | D35: =Inputs!B16 -> 0 | E35: =(E34+Projection!J33)*(1+C35) -> 163850.78 | F35: =E35/(1+Inputs!B16)^(28+1) -> 163850.78 | G35: -0.1 | H35: -0.099 | I35: =(I34+Projection!J33)*(1+G35) -> 40536.345 | J35: =I35/PRODUCT(1+H$7:H35) -> 44990.394 | K35: =Inputs!B17 -> 0.065 | L35: =Inputs!B16 -> 0 | M35: =(M34+Projection!J33)*(1+K35) -> 163850.78 | N35: =M35/PRODUCT(1+L$7:L35) -> 163850.78 | O35: =Inputs!B17 -> 0.065 | P35: =Inputs!B16 -> 0 | Q35: =(Q34+Projection!J33)*(1+O35) -> 163850.78 | R35: =Q35/PRODUCT(1+P$7:P35) -> 163850.78
A36: 29 | B36: 29 | C36: =Inputs!B17 -> 0.065 | D36: =Inputs!B16 -> 0 | E36: =(E35+Projection!J34)*(1+C36) -> 176969.17 | F36: =E36/(1+Inputs!B16)^(29+1) -> 176969.17 | G36: 0.55 | H36: 0.008 | I36: =(I35+Projection!J34)*(1+G36) -> 66423.386 | J36: =I36/PRODUCT(1+H$7:H36) -> 65896.216 | K36: =Inputs!B17 -> 0.065 | L36: =Inputs!B16 -> 0 | M36: =(M35+Projection!J34)*(1+K36) -> 176969.17 | N36: =M36/PRODUCT(1+L$7:L36) -> 176969.17 | O36: =Inputs!B17 -> 0.065 | P36: =Inputs!B16 -> 0 | Q36: =(Q35+Projection!J34)*(1+O36) -> 176969.17 | R36: =Q36/PRODUCT(1+P$7:P36) -> 176969.17
A37: 30 | B37: 30 | C37: =Inputs!B17 -> 0.065 | D37: =Inputs!B16 -> 0 | E37: =(E36+Projection!J35)*(1+C37) -> 190977.09 | F37: =E37/(1+Inputs!B16)^(30+1) -> 190977.09 | G37: -0.02 | H37: 0.014 | I37: =(I36+Projection!J35)*(1+G37) -> 67399.918 | J37: =I37/PRODUCT(1+H$7:H37) -> 66469.347 | K37: -0.1 | L37: 0.029 | M37: =(M36+Projection!J35)*(1+K37) -> 161389.09 | N37: =M37/PRODUCT(1+L$7:L37) -> 156840.71 | O37: =Inputs!B17 -> 0.065 | P37: =Inputs!B16 -> 0 | Q37: =(Q36+Projection!J35)*(1+O37) -> 190977.09 | R37: =Q37/PRODUCT(1+P$7:P37) -> 190977.09
A38: 31 | B38: 31 | C38: =Inputs!B17 -> 0.065 | D38: =Inputs!B16 -> 0 | E38: =(E37+Projection!J36)*(1+C38) -> 205932.91 | F38: =E38/(1+Inputs!B16)^(31+1) -> 205932.91 | G38: 0.46 | H38: 0.029 | I38: =(I37+Projection!J36)*(1+G38) -> 101889.11 | J38: =I38/PRODUCT(1+H$7:H38) -> 99017.603 | K38: 0.24 | L38: 0.031 | M38: =(M37+Projection!J36)*(1+K38) -> 203082.53 | N38: =M38/PRODUCT(1+L$7:L38) -> 196976.27 | O38: =Inputs!B17 -> 0.065 | P38: =Inputs!B16 -> 0 | Q38: =(Q37+Projection!J36)*(1+O38) -> 205932.91 | R38: =Q38/PRODUCT(1+P$7:P38) -> 205932.91
A39: 32 | B39: 32 | C39: =Inputs!B17 -> 0.065 | D39: =Inputs!B16 -> 0 | E39: =(E38+Projection!J37)*(1+C39) -> 221898.8 | F39: =E39/(1+Inputs!B16)^(32+1) -> 221898.8 | G39: 0.32 | H39: 0.012 | I39: =(I38+Projection!J37)*(1+G39) -> 137691.69 | J39: =I39/PRODUCT(1+H$7:H39) -> 136058.98 | K39: 0.11 | L39: 0.044 | M39: =(M38+Projection!J37)*(1+K39) -> 228110.89 | N39: =M39/PRODUCT(1+L$7:L39) -> 218497.02 | O39: =Inputs!B17 -> 0.065 | P39: =Inputs!B16 -> 0 | Q39: =(Q38+Projection!J37)*(1+O39) -> 221898.8 | R39: =Q39/PRODUCT(1+P$7:P39) -> 221898.8
A40: 33 | B40: 33 | C40: =Inputs!B17 -> 0.065 | D40: =Inputs!B16 -> 0 | E40: =(E39+Projection!J38)*(1+C40) -> 238940.99 | F40: =E40/(1+Inputs!B16)^(33+1) -> 238940.99 | G40: -0.36 | H40: 0.029 | I40: =(I39+Projection!J38)*(1+G40) -> 89696.402 | J40: =I40/PRODUCT(1+H$7:H40) -> 87168.515 | K40: -0.08 | L40: 0.054 | M40: =(M39+Projection!J38)*(1+K40) -> 212124.24 | N40: =M40/PRODUCT(1+L$7:L40) -> 201256.39 | O40: =Inputs!B17 -> 0.065 | P40: =Inputs!B16 -> 0 | Q40: =(Q39+Projection!J38)*(1+O40) -> 238940.99 | R40: =Q40/PRODUCT(1+P$7:P40) -> 238940.99
A41: 34 | B41: 34 | C41: =Inputs!B17 -> 0.065 | D41: =Inputs!B16 -> 0 | E41: =(E40+Projection!J39)*(1+C41) -> 257130.01 | F41: =E41/(1+Inputs!B16)^(34+1) -> 257130.01 | G41: 0.3 | H41: -0.02 | I41: =(I40+Projection!J39)*(1+G41) -> 119849.65 | J41: =I41/PRODUCT(1+H$7:H41) -> 122295.56 | K41: 0.04 | L41: 0.058 | M41: =(M40+Projection!J39)*(1+K41) -> 223204.67 | N41: =M41/PRODUCT(1+L$7:L41) -> 210968.5 | O41: =Inputs!B17 -> 0.065 | P41: =Inputs!B16 -> 0 | Q41: =(Q40+Projection!J39)*(1+O41) -> 257130.01 | R41: =Q41/PRODUCT(1+P$7:P41) -> 257130.01
...

Sheet Mode Presets
A1: Mode reference values from the paper
A2: Copy these into the Inputs sheet to replay any of the three constitutional Modes.
A3: What each Mode optimizes
A4: Parameter | B4: Mode A — Maximum wealth (deflation) | C4: Mode B — Stable prices (neutral) | D4: Mode C — Monthly dividend (inflation) | E4: Notes
A5: K1 — Citizenship | B5: 2.5% | C5: 2.5% | D5: 2.5% | E5: Identical across modes — anchor the citizenship endowment.
A6: K2 — Growth | B6: 12.5% | C6: 84% | D6: 12.5% | E6: Mode B raises K2 share to absorb full real-growth issuance.
A7: K3 — Dividend | B7: 0% | C7: 0% | D7: ~4.0% | E7: Mode C only. Calibrated by price-level path targeting.
A8: CPI target | B8: -1.6% | C8: 0% | D8: +2.0% | E8: The defining macro outcome of each mode.
A9: Stable Floor at 65 (real) | B9: $1.7M | C9: $2.6M | D9: $145K | E9: Mode A wins on long-run wealth; Mode C trades it for dividends.
A10: Annual real income at 65 | B10: $68K | C10: $105K | D10: $5.8K + K3 | E10: 4% withdrawal rate, plus ongoing K3 in Mode C.
A11: K3 monthly dividend, yr 1 | B11: $0 | C11: $0 | D11: $208 | E11: Per citizen, rises with M2 over time.
A12: Total issuance / M2 | B12: ~0.35% | C12: ~2.5% | D12: ~4.1% | E12: Annual issuance as fraction of money supply.
A13: Constitutional change | B13: Tier 2: 67% supermajority + 90-day deliberation | E13: Modes do NOT auto-rotate. Selection is a constitutional act.
A15: Mode philosophy
A16: Mode A | B16: Maximum lifetime wealth via gentle deflation. No monthly dividend. K2 contracts to ~12.5% so most of real growth flows to falling prices rather than expanding M2. The Stable Floor compounds aggressively because purchasing power rises over time. Best for retirement-focused societies.
A17: Mode B | B17: Price stability. K2 expanded to ~84% so circulating money matches real growth exactly — no monetary inflation, no monetary deflation. Highest possible Stable Floor wealth without dividend. Default neutral mode.
A18: Mode C | B18: Monthly citizen dividend at the cost of lower locked wealth. K3 activates (~4% of M2) and is calibrated by price-level path targeting to hit ~2% inflation. Citizens get ~$208/month at launch (rising over time) plus a smaller Stable Floor.

Sheet How It Works
A1: Formula reference and assumptions — Interactive Model Builder
A3: Architecture
A4: Two pools | B4: Circulating money (M2) and the Citizen Equity Stake (Stable Floor). They intersect only at K1/K2 issuance and at retirement withdrawals.
A5: Three channels | B5: K1 fires once per new citizen. K2 fires every year. K3 fires monthly (active in Mode C).
A7: K1 formula | B7: K1 total = K1_share × (GDP / population) × births_this_year
A8: K2 formula | B8: K2 total = K2_share × (GDP × real_growth_rate)
A9: K3 formula | B9: K3 total = K3_share × M2 (paper uses price-level path targeting; this engine uses a flat % of M2 as the simplified equivalent)
A11: Stable Floor | B11: For our representative cohort (born at t=0): floor compounds at the equity return rate. K1 is deposited once at birth; K2 is deposited every year. Both lock until retirement.
A12: Real values | B12: CPI index starts at 1.0 and grows at the CPI inflation rate. Real value = nominal / CPI index.
A13: K3 distribution | B13: K3 is unlocked, immediately spendable, deposited monthly into citizen transaction accounts.
A15: Simplifications | B15: This engine is a single-cohort projection with constant rates. The full paper models stochastic returns, mode transitions, sequence-of-returns risk, and emergency tools. Use this for intuition, not policy calibration.
A16: Equity return | B16: Treated as nominal in this model. If you want real returns, set CPI=0 and the equity return is automatically real.
A17: Births formula | B17: Births = pop × pop_growth_rate. Real demographics are more complex; this is a proxy.
A18: Mode C K3 calibration | B18: The paper calibrates K3 dynamically to close the cumulative CPI gap. Setting K3 to a flat ~4% of M2 reproduces the launch-year value but not the dynamic behavior.
... A27: Stress Test sheet | B27: Year-by-year simulation of the Stable Floor under three real historical adverse sequences (Great Depression 1929-1944, 1970s Stagflation 1966-1982, 2000s Lost Decade 2000-2009) plus the smooth baseline. Returns and CPI for stress periods come from Robert Shiller's dataset and BLS historical CPI. Headline outputs at top show Stable Floor at horizon, 4% withdrawal income, percent change vs. baseline, and the multiple of $87,571 (median American 401k at 55-64). Adjust your equity return and CPI inputs on the Inputs sheet to see how different baseline assumptions change the stress test outcomes.
